Workbook

Sheet Instrucciones
A1: QUINIELA MUNDIAL DE FÚTBOL 2026 - 100% AUTOMATIZADA
A4: CÓMO FUNCIONA:
A5: 1. Pestaña 'Grupos': Ingresa los resultados. Las tablas se calculan en tiempo real.
A6: 2. Pestaña 'Eliminatorias': Al ir llenando, verás cómo los nombres se auto-completan gracias a la corrección del motor.
A7: 3. Puedes empezar a llenar y los líderes de cada grupo aparecerán de inmediato.
A9: Sistema de Puntuación
A11: Fase de Grupos:
A13: 3 puntos por acertar el marcador exacto de un partido.
A14: 1 punto por acertar el resultado (ganador o empate) sin atinarle al marcador exacto.
A16: Fase Eliminatoria:
A18: 5 puntos por acertar el marcador exacto (solo si atinaste a los equipos que jugaban).
A19: 2 puntos por acertar al ganador del partido.
... A31: 10 puntos al acertar al 3er Lugar.
G34: Desarrollado por:
G35: Salvador Velasco Téllez
G36: salvador.velasco@gmail.com

Sheet Grupos
A1: PARTIDOS DE GRUPOS | J1: TABLAS DE POSICIONES (AUTOMÁTICAS)
A4: ID | B4: Grupo | C4: Equipo 1 | D4: Goles | E4: vs | F4: Goles | G4: Equipo 2 | H4: Estado | J4: Grupo | K4: Equipo | L4: PJ | M4: PG | N4: PE | O4: PP | P4: GF | Q4: GC | R4: DIF | S4: PTS | T4: SCORE TIEBREAK
A5: GRUPO A | J5: CLASIFICACIÓN GRUPO A
C6: México | E6: - | G6: Sudáfrica | H6: =IF(AND(ISNUMBER(D6),ISNUMBER(F6)),"Ok","") | J6: A | K6: México | L6: =IF(ISNUMBER(D6),1,0)+IF(ISNUMBER(D8),1,0)+IF(ISNUMBER(F10),1,0) -> 0 | M6: =IF(AND(ISNUMBER(D6),ISNUMBER(F6),D6>F6),1,0)+IF(AND(ISNUMBER(D8),ISNUMBER(F8),D8>F8),1,0)+IF(AND(ISNUMBER(F10),ISNUMBER(D10),F10>D10),1,0) -> 0 | N6: =IF(AND(ISNUMBER(D6),ISNUMBER(F6),D6=F6),1,0)+IF(AND(ISNUMBER(D8),ISNUMBER(F8),D8=F8),1,0)+IF(AND(ISNUMBER(F10),ISNUMBER(D10),F10=D10),1,0) -> 0 | O6: =IF(AND(ISNUMBER(D6),ISNUMBER(F6),D6<F6),1,0)+IF(AND(ISNUMBER(D8),ISNUMBER(F8),D8<F8),1,0)+IF(AND(ISNUMBER(F10),ISNUMBER(D10),F10<D10),1,0) -> 0 | P6: =IF(ISNUMBER(D6),D6,0)+IF(ISNUMBER(D8),D8,0)+IF(ISNUMBER(F10),F10,0) -> 0 | Q6: =IF(ISNUMBER(F6),F6,0)+IF(ISNUMBER(F8),F8,0)+IF(ISNUMBER(D10),D10,0) -> 0 | R6: =P6-Q6 -> 0 | S6: =M6*3+N6 -> 0 | T6: =S6*1000000 + (R6+100)*1000 + P6 + (ROW()/10000) -> 100000
C7: Corea del Sur | E7: - | G7: Chequia | H7: =IF(AND(ISNUMBER(D7),ISNUMBER(F7)),"Ok","") | J7: A | K7: Sudáfrica | L7: =IF(ISNUMBER(F6),1,0)+IF(ISNUMBER(D9),1,0)+IF(ISNUMBER(D11),1,0) -> 0 | M7: =IF(AND(ISNUMBER(F6),ISNUMBER(D6),F6>D6),1,0)+IF(AND(ISNUMBER(D9),ISNUMBER(F9),D9>F9),1,0)+IF(AND(ISNUMBER(D11),ISNUMBER(F11),D11>F11),1,0) -> 0 | N7: =IF(AND(ISNUMBER(F6),ISNUMBER(D6),F6=D6),1,0)+IF(AND(ISNUMBER(D9),ISNUMBER(F9),D9=F9),1,0)+IF(AND(ISNUMBER(D11),ISNUMBER(F11),D11=F11),1,0) -> 0 | O7: =IF(AND(ISNUMBER(F6),ISNUMBER(D6),F6<D6),1,0)+IF(AND(ISNUMBER(D9),ISNUMBER(F9),D9<F9),1,0)+IF(AND(ISNUMBER(D11),ISNUMBER(F11),D11<F11),1,0) -> 0 | P7: =IF(ISNUMBER(F6),F6,0)+IF(ISNUMBER(D9),D9,0)+IF(ISNUMBER(D11),D11,0) -> 0 | Q7: =IF(ISNUMBER(D6),D6,0)+IF(ISNUMBER(F9),F9,0)+IF(ISNUMBER(F11),F11,0) -> 0 | R7: =P7-Q7 -> 0 | S7: =M7*3+N7 -> 0 | T7: =S7*1000000 + (R7+100)*1000 + P7 + (ROW()/10000) -> 100000
C8: México | E8: - | G8: Corea del Sur | H8: =IF(AND(ISNUMBER(D8),ISNUMBER(F8)),"Ok","") | J8: A | K8: Corea del Sur | L8: =IF(ISNUMBER(D7),1,0)+IF(ISNUMBER(F8),1,0)+IF(ISNUMBER(F11),1,0) -> 0 | M8: =IF(AND(ISNUMBER(D7),ISNUMBER(F7),D7>F7),1,0)+IF(AND(ISNUMBER(F8),ISNUMBER(D8),F8>D8),1,0)+IF(AND(ISNUMBER(F11),ISNUMBER(D11),F11>D11),1,0) -> 0 | N8: =IF(AND(ISNUMBER(D7),ISNUMBER(F7),D7=F7),1,0)+IF(AND(ISNUMBER(F8),ISNUMBER(D8),F8=D8),1,0)+IF(AND(ISNUMBER(F11),ISNUMBER(D11),F11=D11),1,0) -> 0 | O8: =IF(AND(ISNUMBER(D7),ISNUMBER(F7),D7<F7),1,0)+IF(AND(ISNUMBER(F8),ISNUMBER(D8),F8<D8),1,0)+IF(AND(ISNUMBER(F11),ISNUMBER(D11),F11<D11),1,0) -> 0 | P8: =IF(ISNUMBER(D7),D7,0)+IF(ISNUMBER(F8),F8,0)+IF(ISNUMBER(F11),F11,0) -> 0 | Q8: =IF(ISNUMBER(F7),F7,0)+IF(ISNUMBER(D8),D8,0)+IF(ISNUMBER(D11),D11,0) -> 0 | R8: =P8-Q8 -> 0 | S8: =M8*3+N8 -> 0 | T8: =S8*1000000 + (R8+100)*1000 + P8 + (ROW()/10000) -> 100000
C9: Sudáfrica | E9: - | G9: Chequia | H9: =IF(AND(ISNUMBER(D9),ISNUMBER(F9)),"Ok","") | J9: A | K9: Chequia | L9: =IF(ISNUMBER(F7),1,0)+IF(ISNUMBER(F9),1,0)+IF(ISNUMBER(D10),1,0) -> 0 | M9: =IF(AND(ISNUMBER(F7),ISNUMBER(D7),F7>D7),1,0)+IF(AND(ISNUMBER(F9),ISNUMBER(D9),F9>D9),1,0)+IF(AND(ISNUMBER(D10),ISNUMBER(F10),D10>F10),1,0) -> 0 | N9: =IF(AND(ISNUMBER(F7),ISNUMBER(D7),F7=D7),1,0)+IF(AND(ISNUMBER(F9),ISNUMBER(D9),F9=D9),1,0)+IF(AND(ISNUMBER(D10),ISNUMBER(F10),D10=F10),1,0) -> 0 | O9: =IF(AND(ISNUMBER(F7),ISNUMBER(D7),F7<D7),1,0)+IF(AND(ISNUMBER(F9),ISNUMBER(D9),F9<D9),1,0)+IF(AND(ISNUMBER(D10),ISNUMBER(F10),D10<F10),1,0) -> 0 | P9: =IF(ISNUMBER(F7),F7,0)+IF(ISNUMBER(F9),F9,0)+IF(ISNUMBER(D10),D10,0) -> 0 | Q9: =IF(ISNUMBER(D7),D7,0)+IF(ISNUMBER(D9),D9,0)+IF(ISNUMBER(F10),F10,0) -> 0 | R9: =P9-Q9 -> 0 | S9: =M9*3+N9 -> 0 | T9: =S9*1000000 + (R9+100)*1000 + P9 + (ROW()/10000) -> 100000
C10: Chequia | E10: - | G10: México | H10: =IF(AND(ISNUMBER(D10),ISNUMBER(F10)),"Ok","")
C11: Sudáfrica | E11: - | G11: Corea del Sur | H11: =IF(AND(ISNUMBER(D11),ISNUMBER(F11)),"Ok","") | J11: CLASIFICACIÓN GRUPO B
J12: B | K12: Canadá | L12: =IF(ISNUMBER(D14),1,0)+IF(ISNUMBER(D16),1,0)+IF(ISNUMBER(F18),1,0) -> 0 | M12: =IF(AND(ISNUMBER(D14),ISNUMBER(F14),D14>F14),1,0)+IF(AND(ISNUMBER(D16),ISNUMBER(F16),D16>F16),1,0)+IF(AND(ISNUMBER(F18),ISNUMBER(D18),F18>D18),1,0) -> 0 | N12: =IF(AND(ISNUMBER(D14),ISNUMBER(F14),D14=F14),1,0)+IF(AND(ISNUMBER(D16),ISNUMBER(F16),D16=F16),1,0)+IF(AND(ISNUMBER(F18),ISNUMBER(D18),F18=D18),1,0) -> 0 | O12: =IF(AND(ISNUMBER(D14),ISNUMBER(F14),D14<F14),1,0)+IF(AND(ISNUMBER(D16),ISNUMBER(F16),D16<F16),1,0)+IF(AND(ISNUMBER(F18),ISNUMBER(D18),F18<D18),1,0) -> 0 | P12: =IF(ISNUMBER(D14),D14,0)+IF(ISNUMBER(D16),D16,0)+IF(ISNUMBER(F18),F18,0) -> 0 | Q12: =IF(ISNUMBER(F14),F14,0)+IF(ISNUMBER(F16),F16,0)+IF(ISNUMBER(D18),D18,0) -> 0 | R12: =P12-Q12 -> 0 | S12: =M12*3+N12 -> 0 | T12: =S12*1000000 + (R12+100)*1000 + P12 + (ROW()/10000) -> 100000
A13: GRUPO B | J13: B | K13: Bosnia y Herze. | L13: =IF(ISNUMBER(F14),1,0)+IF(ISNUMBER(D17),1,0)+IF(ISNUMBER(D19),1,0) -> 0 | M13: =IF(AND(ISNUMBER(F14),ISNUMBER(D14),F14>D14),1,0)+IF(AND(ISNUMBER(D17),ISNUMBER(F17),D17>F17),1,0)+IF(AND(ISNUMBER(D19),ISNUMBER(F19),D19>F19),1,0) -> 0 | N13: =IF(AND(ISNUMBER(F14),ISNUMBER(D14),F14=D14),1,0)+IF(AND(ISNUMBER(D17),ISNUMBER(F17),D17=F17),1,0)+IF(AND(ISNUMBER(D19),ISNUMBER(F19),D19=F19),1,0) -> 0 | O13: =IF(AND(ISNUMBER(F14),ISNUMBER(D14),F14<D14),1,0)+IF(AND(ISNUMBER(D17),ISNUMBER(F17),D17<F17),1,0)+IF(AND(ISNUMBER(D19),ISNUMBER(F19),D19<F19),1,0) -> 0 | P13: =IF(ISNUMBER(F14),F14,0)+IF(ISNUMBER(D17),D17,0)+IF(ISNUMBER(D19),D19,0) -> 0 | Q13: =IF(ISNUMBER(D14),D14,0)+IF(ISNUMBER(F17),F17,0)+IF(ISNUMBER(F19),F19,0) -> 0 | R13: =P13-Q13 -> 0 | S13: =M13*3+N13 -> 0 | T13: =S13*1000000 + (R13+100)*1000 + P13 + (ROW()/10000) -> 100000
C14: Canadá | E14: - | G14: Bosnia y Herze. | H14: =IF(AND(ISNUMBER(D14),ISNUMBER(F14)),"Ok","") | J14: B | K14: Qatar | L14: =IF(ISNUMBER(D15),1,0)+IF(ISNUMBER(F16),1,0)+IF(ISNUMBER(F19),1,0) -> 0 | M14: =IF(AND(ISNUMBER(D15),ISNUMBER(F15),D15>F15),1,0)+IF(AND(ISNUMBER(F16),ISNUMBER(D16),F16>D16),1,0)+IF(AND(ISNUMBER(F19),ISNUMBER(D19),F19>D19),1,0) -> 0 | N14: =IF(AND(ISNUMBER(D15),ISNUMBER(F15),D15=F15),1,0)+IF(AND(ISNUMBER(F16),ISNUMBER(D16),F16=D16),1,0)+IF(AND(ISNUMBER(F19),ISNUMBER(D19),F19=D19),1,0) -> 0 | O14: =IF(AND(ISNUMBER(D15),ISNUMBER(F15),D15<F15),1,0)+IF(AND(ISNUMBER(F16),ISNUMBER(D16),F16<D16),1,0)+IF(AND(ISNUMBER(F19),ISNUMBER(D19),F19<D19),1,0) -> 0 | P14: =IF(ISNUMBER(D15),D15,0)+IF(ISNUMBER(F16),F16,0)+IF(ISNUMBER(F19),F19,0) -> 0 | Q14: =IF(ISNUMBER(F15),F15,0)+IF(ISNUMBER(D16),D16,0)+IF(ISNUMBER(D19),D19,0) -> 0 | R14: =P14-Q14 -> 0 | S14: =M14*3+N14 -> 0 | T14: =S14*1000000 + (R14+100)*1000 + P14 + (ROW()/10000) -> 100000
C15: Qatar | E15: - | G15: Suiza | H15: =IF(AND(ISNUMBER(D15),ISNUMBER(F15)),"Ok","") | J15: B | K15: Suiza | L15: =IF(ISNUMBER(F15),1,0)+IF(ISNUMBER(F17),1,0)+IF(ISNUMBER(D18),1,0) -> 0 | M15: =IF(AND(ISNUMBER(F15),ISNUMBER(D15),F15>D15),1,0)+IF(AND(ISNUMBER(F17),ISNUMBER(D17),F17>D17),1,0)+IF(AND(ISNUMBER(D18),ISNUMBER(F18),D18>F18),1,0) -> 0 | N15: =IF(AND(ISNUMBER(F15),ISNUMBER(D15),F15=D15),1,0)+IF(AND(ISNUMBER(F17),ISNUMBER(D17),F17=D17),1,0)+IF(AND(ISNUMBER(D18),ISNUMBER(F18),D18=F18),1,0) -> 0 | O15: =IF(AND(ISNUMBER(F15),ISNUMBER(D15),F15<D15),1,0)+IF(AND(ISNUMBER(F17),ISNUMBER(D17),F17<D17),1,0)+IF(AND(ISNUMBER(D18),ISNUMBER(F18),D18<F18),1,0) -> 0 | P15: =IF(ISNUMBER(F15),F15,0)+IF(ISNUMBER(F17),F17,0)+IF(ISNUMBER(D18),D18,0) -> 0 | Q15: =IF(ISNUMBER(D15),D15,0)+IF(ISNUMBER(D17),D17,0)+IF(ISNUMBER(F18),F18,0) -> 0 | R15: =P15-Q15 -> 0 | S15: =M15*3+N15 -> 0 | T15: =S15*1000000 + (R15+100)*1000 + P15 + (ROW()/10000) -> 100000
C16: Canadá | E16: - | G16: Qatar | H16: =IF(AND(ISNUMBER(D16),ISNUMBER(F16)),"Ok","")
C17: Bosnia y Herze. | E17: - | G17: Suiza | H17: =IF(AND(ISNUMBER(D17),ISNUMBER(F17)),"Ok","") | J17: CLASIFICACIÓN GRUPO C
C18: Suiza | E18: - | G18: Canadá | H18: =IF(AND(ISNUMBER(D18),ISNUMBER(F18)),"Ok","") | J18: C | K18: Brasil | L18: =IF(ISNUMBER(D22),1,0)+IF(ISNUMBER(D24),1,0)+IF(ISNUMBER(F26),1,0) -> 0 | M18: =IF(AND(ISNUMBER(D22),ISNUMBER(F22),D22>F22),1,0)+IF(AND(ISNUMBER(D24),ISNUMBER(F24),D24>F24),1,0)+IF(AND(ISNUMBER(F26),ISNUMBER(D26),F26>D26),1,0) -> 0 | N18: =IF(AND(ISNUMBER(D22),ISNUMBER(F22),D22=F22),1,0)+IF(AND(ISNUMBER(D24),ISNUMBER(F24),D24=F24),1,0)+IF(AND(ISNUMBER(F26),ISNUMBER(D26),F26=D26),1,0) -> 0 | O18: =IF(AND(ISNUMBER(D22),ISNUMBER(F22),D22<F22),1,0)+IF(AND(ISNUMBER(D24),ISNUMBER(F24),D24<F24),1,0)+IF(AND(ISNUMBER(F26),ISNUMBER(D26),F26<D26),1,0) -> 0 | P18: =IF(ISNUMBER(D22),D22,0)+IF(ISNUMBER(D24),D24,0)+IF(ISNUMBER(F26),F26,0) -> 0 | Q18: =IF(ISNUMBER(F22),F22,0)+IF(ISNUMBER(F24),F24,0)+IF(ISNUMBER(D26),D26,0) -> 0 | R18: =P18-Q18 -> 0 | S18: =M18*3+N18 -> 0 | T18: =S18*1000000 + (R18+100)*1000 + P18 + (ROW()/10000) -> 100000
C19: Bosnia y Herze. | E19: - | G19: Qatar | H19: =IF(AND(ISNUMBER(D19),ISNUMBER(F19)),"Ok","") | J19: C | K19: Marruecos | L19: =IF(ISNUMBER(F22),1,0)+IF(ISNUMBER(D25),1,0)+IF(ISNUMBER(D27),1,0) -> 0 | M19: =IF(AND(ISNUMBER(F22),ISNUMBER(D22),F22>D22),1,0)+IF(AND(ISNUMBER(D25),ISNUMBER(F25),D25>F25),1,0)+IF(AND(ISNUMBER(D27),ISNUMBER(F27),D27>F27),1,0) -> 0 | N19: =IF(AND(ISNUMBER(F22),ISNUMBER(D22),F22=D22),1,0)+IF(AND(ISNUMBER(D25),ISNUMBER(F25),D25=F25),1,0)+IF(AND(ISNUMBER(D27),ISNUMBER(F27),D27=F27),1,0) -> 0 | O19: =IF(AND(ISNUMBER(F22),ISNUMBER(D22),F22<D22),1,0)+IF(AND(ISNUMBER(D25),ISNUMBER(F25),D25<F25),1,0)+IF(AND(ISNUMBER(D27),ISNUMBER(F27),D27<F27),1,0) -> 0 | P19: =IF(ISNUMBER(F22),F22,0)+IF(ISNUMBER(D25),D25,0)+IF(ISNUMBER(D27),D27,0) -> 0 | Q19: =IF(ISNUMBER(D22),D22,0)+IF(ISNUMBER(F25),F25,0)+IF(ISNUMBER(F27),F27,0) -> 0 | R19: =P19-Q19 -> 0 | S19: =M19*3+N19 -> 0 | T19: =S19*1000000 + (R19+100)*1000 + P19 + (ROW()/10000) -> 100000
J20: C | K20: Haití | L20: =IF(ISNUMBER(D23),1,0)+IF(ISNUMBER(F24),1,0)+IF(ISNUMBER(F27),1,0) -> 0 | M20: =IF(AND(ISNUMBER(D23),ISNUMBER(F23),D23>F23),1,0)+IF(AND(ISNUMBER(F24),ISNUMBER(D24),F24>D24),1,0)+IF(AND(ISNUMBER(F27),ISNUMBER(D27),F27>D27),1,0) -> 0 | N20: =IF(AND(ISNUMBER(D23),ISNUMBER(F23),D23=F23),1,0)+IF(AND(ISNUMBER(F24),ISNUMBER(D24),F24=D24),1,0)+IF(AND(ISNUMBER(F27),ISNUMBER(D27),F27=D27),1,0) -> 0 | O20: =IF(AND(ISNUMBER(D23),ISNUMBER(F23),D23<F23),1,0)+IF(AND(ISNUMBER(F24),ISNUMBER(D24),F24<D24),1,0)+IF(AND(ISNUMBER(F27),ISNUMBER(D27),F27<D27),1,0) -> 0 | P20: =IF(ISNUMBER(D23),D23,0)+IF(ISNUMBER(F24),F24,0)+IF(ISNUMBER(F27),F27,0) -> 0 | Q20: =IF(ISNUMBER(F23),F23,0)+IF(ISNUMBER(D24),D24,0)+IF(ISNUMBER(D27),D27,0) -> 0 | R20: =P20-Q20 -> 0 | S20: =M20*3+N20 -> 0 | T20: =S20*1000000 + (R20+100)*1000 + P20 + (ROW()/10000) -> 100000
A21: GRUPO C | J21: C | K21: Escocia | L21: =IF(ISNUMBER(F23),1,0)+IF(ISNUMBER(F25),1,0)+IF(ISNUMBER(D26),1,0) -> 0 | M21: =IF(AND(ISNUMBER(F23),ISNUMBER(D23),F23>D23),1,0)+IF(AND(ISNUMBER(F25),ISNUMBER(D25),F25>D25),1,0)+IF(AND(ISNUMBER(D26),ISNUMBER(F26),D26>F26),1,0) -> 0 | N21: =IF(AND(ISNUMBER(F23),ISNUMBER(D23),F23=D23),1,0)+IF(AND(ISNUMBER(F25),ISNUMBER(D25),F25=D25),1,0)+IF(AND(ISNUMBER(D26),ISNUMBER(F26),D26=F26),1,0) -> 0 | O21: =IF(AND(ISNUMBER(F23),ISNUMBER(D23),F23<D23),1,0)+IF(AND(ISNUMBER(F25),ISNUMBER(D25),F25<D25),1,0)+IF(AND(ISNUMBER(D26),ISNUMBER(F26),D26<F26),1,0) -> 0 | P21: =IF(ISNUMBER(F23),F23,0)+IF(ISNUMBER(F25),F25,0)+IF(ISNUMBER(D26),D26,0) -> 0 | Q21: =IF(ISNUMBER(D23),D23,0)+IF(ISNUMBER(D25),D25,0)+IF(ISNUMBER(F26),F26,0) -> 0 | R21: =P21-Q21 -> 0 | S21: =M21*3+N21 -> 0 | T21: =S21*1000000 + (R21+100)*1000 + P21 + (ROW()/10000) -> 100000
C22: Brasil | E22: - | G22: Marruecos | H22: =IF(AND(ISNUMBER(D22),ISNUMBER(F22)),"Ok","")
C23: Haití | E23: - | G23: Escocia | H23: =IF(AND(ISNUMBER(D23),ISNUMBER(F23)),"Ok","") | J23: CLASIFICACIÓN GRUPO D
C24: Brasil | E24: - | G24: Haití | H24: =IF(AND(ISNUMBER(D24),ISNUMBER(F24)),"Ok","") | J24: D | K24: Estados Unidos | L24: =IF(ISNUMBER(D30),1,0)+IF(ISNUMBER(D32),1,0)+IF(ISNUMBER(F34),1,0) -> 0 | M24: =IF(AND(ISNUMBER(D30),ISNUMBER(F30),D30>F30),1,0)+IF(AND(ISNUMBER(D32),ISNUMBER(F32),D32>F32),1,0)+IF(AND(ISNUMBER(F34),ISNUMBER(D34),F34>D34),1,0) -> 0 | N24: =IF(AND(ISNUMBER(D30),ISNUMBER(F30),D30=F30),1,0)+IF(AND(ISNUMBER(D32),ISNUMBER(F32),D32=F32),1,0)+IF(AND(ISNUMBER(F34),ISNUMBER(D34),F34=D34),1,0) -> 0 | O24: =IF(AND(ISNUMBER(D30),ISNUMBER(F30),D30<F30),1,0)+IF(AND(ISNUMBER(D32),ISNUMBER(F32),D32<F32),1,0)+IF(AND(ISNUMBER(F34),ISNUMBER(D34),F34<D34),1,0) -> 0 | P24: =IF(ISNUMBER(D30),D30,0)+IF(ISNUMBER(D32),D32,0)+IF(ISNUMBER(F34),F34,0) -> 0 | Q24: =IF(ISNUMBER(F30),F30,0)+IF(ISNUMBER(F32),F32,0)+IF(ISNUMBER(D34),D34,0) -> 0 | R24: =P24-Q24 -> 0 | S24: =M24*3+N24 -> 0 | T24: =S24*1000000 + (R24+100)*1000 + P24 + (ROW()/10000) -> 100000
C25: Marruecos | E25: - | G25: Escocia | H25: =IF(AND(ISNUMBER(D25),ISNUMBER(F25)),"Ok","") | J25: D | K25: Paraguay | L25: =IF(ISNUMBER(F30),1,0)+IF(ISNUMBER(D33),1,0)+IF(ISNUMBER(D35),1,0) -> 0 | M25: =IF(AND(ISNUMBER(F30),ISNUMBER(D30),F30>D30),1,0)+IF(AND(ISNUMBER(D33),ISNUMBER(F33),D33>F33),1,0)+IF(AND(ISNUMBER(D35),ISNUMBER(F35),D35>F35),1,0) -> 0 | N25: =IF(AND(ISNUMBER(F30),ISNUMBER(D30),F30=D30),1,0)+IF(AND(ISNUMBER(D33),ISNUMBER(F33),D33=F33),1,0)+IF(AND(ISNUMBER(D35),ISNUMBER(F35),D35=F35),1,0) -> 0 | O25: =IF(AND(ISNUMBER(F30),ISNUMBER(D30),F30<D30),1,0)+IF(AND(ISNUMBER(D33),ISNUMBER(F33),D33<F33),1,0)+IF(AND(ISNUMBER(D35),ISNUMBER(F35),D35<F35),1,0) -> 0 | P25: =IF(ISNUMBER(F30),F30,0)+IF(ISNUMBER(D33),D33,0)+IF(ISNUMBER(D35),D35,0) -> 0 | Q25: =IF(ISNUMBER(D30),D30,0)+IF(ISNUMBER(F33),F33,0)+IF(ISNUMBER(F35),F35,0) -> 0 | R25: =P25-Q25 -> 0 | S25: =M25*3+N25 -> 0 | T25: =S25*1000000 + (R25+100)*1000 + P25 + (ROW()/10000) -> 100000
C26: Escocia | E26: - | G26: Brasil | H26: =IF(AND(ISNUMBER(D26),ISNUMBER(F26)),"Ok","") | J26: D | K26: Australia | L26: =IF(ISNUMBER(D31),1,0)+IF(ISNUMBER(F32),1,0)+IF(ISNUMBER(F35),1,0) -> 0 | M26: =IF(AND(ISNUMBER(D31),ISNUMBER(F31),D31>F31),1,0)+IF(AND(ISNUMBER(F32),ISNUMBER(D32),F32>D32),1,0)+IF(AND(ISNUMBER(F35),ISNUMBER(D35),F35>D35),1,0) -> 0 | N26: =IF(AND(ISNUMBER(D31),ISNUMBER(F31),D31=F31),1,0)+IF(AND(ISNUMBER(F32),ISNUMBER(D32),F32=D32),1,0)+IF(AND(ISNUMBER(F35),ISNUMBER(D35),F35=D35),1,0) -> 0 | O26: =IF(AND(ISNUMBER(D31),ISNUMBER(F31),D31<F31),1,0)+IF(AND(ISNUMBER(F32),ISNUMBER(D32),F32<D32),1,0)+IF(AND(ISNUMBER(F35),ISNUMBER(D35),F35<D35),1,0) -> 0 | P26: =IF(ISNUMBER(D31),D31,0)+IF(ISNUMBER(F32),F32,0)+IF(ISNUMBER(F35),F35,0) -> 0 | Q26: =IF(ISNUMBER(F31),F31,0)+IF(ISNUMBER(D32),D32,0)+IF(ISNUMBER(D35),D35,0) -> 0 | R26: =P26-Q26 -> 0 | S26: =M26*3+N26 -> 0 | T26: =S26*1000000 + (R26+100)*1000 + P26 + (ROW()/10000) -> 100000
C27: Marruecos | E27: - | G27: Haití | H27: =IF(AND(ISNUMBER(D27),ISNUMBER(F27)),"Ok","") | J27: D | K27: Turquía | L27: =IF(ISNUMBER(F31),1,0)+IF(ISNUMBER(F33),1,0)+IF(ISNUMBER(D34),1,0) -> 0 | M27: =IF(AND(ISNUMBER(F31),ISNUMBER(D31),F31>D31),1,0)+IF(AND(ISNUMBER(F33),ISNUMBER(D33),F33>D33),1,0)+IF(AND(ISNUMBER(D34),ISNUMBER(F34),D34>F34),1,0) -> 0 | N27: =IF(AND(ISNUMBER(F31),ISNUMBER(D31),F31=D31),1,0)+IF(AND(ISNUMBER(F33),ISNUMBER(D33),F33=D33),1,0)+IF(AND(ISNUMBER(D34),ISNUMBER(F34),D34=F34),1,0) -> 0 | O27: =IF(AND(ISNUMBER(F31),ISNUMBER(D31),F31<D31),1,0)+IF(AND(ISNUMBER(F33),ISNUMBER(D33),F33<D33),1,0)+IF(AND(ISNUMBER(D34),ISNUMBER(F34),D34<F34),1,0) -> 0 | P27: =IF(ISNUMBER(F31),F31,0)+IF(ISNUMBER(F33),F33,0)+IF(ISNUMBER(D34),D34,0) -> 0 | Q27: =IF(ISNUMBER(D31),D31,0)+IF(ISNUMBER(D33),D33,0)+IF(ISNUMBER(F34),F34,0) -> 0 | R27: =P27-Q27 -> 0 | S27: =M27*3+N27 -> 0 | T27: =S27*1000000 + (R27+100)*1000 + P27 + (ROW()/10000) -> 100000
A29: GRUPO D | J29: CLASIFICACIÓN GRUPO E
C30: Estados Unidos | E30: - | G30: Paraguay | H30: =IF(AND(ISNUMBER(D30),ISNUMBER(F30)),"Ok","") | J30: E | K30: Alemania | L30: =IF(ISNUMBER(D38),1,0)+IF(ISNUMBER(D40),1,0)+IF(ISNUMBER(F42),1,0) -> 0 | M30: =IF(AND(ISNUMBER(D38),ISNUMBER(F38),D38>F38),1,0)+IF(AND(ISNUMBER(D40),ISNUMBER(F40),D40>F40),1,0)+IF(AND(ISNUMBER(F42),ISNUMBER(D42),F42>D42),1,0) -> 0 | N30: =IF(AND(ISNUMBER(D38),ISNUMBER(F38),D38=F38),1,0)+IF(AND(ISNUMBER(D40),ISNUMBER(F40),D40=F40),1,0)+IF(AND(ISNUMBER(F42),ISNUMBER(D42),F42=D42),1,0) -> 0 | O30: =IF(AND(ISNUMBER(D38),ISNUMBER(F38),D38<F38),1,0)+IF(AND(ISNUMBER(D40),ISNUMBER(F40),D40<F40),1,0)+IF(AND(ISNUMBER(F42),ISNUMBER(D42),F42<D42),1,0) -> 0 | P30: =IF(ISNUMBER(D38),D38,0)+IF(ISNUMBER(D40),D40,0)+IF(ISNUMBER(F42),F42,0) -> 0 | Q30: =IF(ISNUMBER(F38),F38,0)+IF(ISNUMBER(F40),F40,0)+IF(ISNUMBER(D42),D42,0) -> 0 | R30: =P30-Q30 -> 0 | S30: =M30*3+N30 -> 0 | T30: =S30*1000000 + (R30+100)*1000 + P30 + (ROW()/10000) -> 100000
C31: Australia | E31: - | G31: Turquía | H31: =IF(AND(ISNUMBER(D31),ISNUMBER(F31)),"Ok","") | J31: E | K31: Curaçao | L31: =IF(ISNUMBER(F38),1,0)+IF(ISNUMBER(D41),1,0)+IF(ISNUMBER(D43),1,0) -> 0 | M31: =IF(AND(ISNUMBER(F38),ISNUMBER(D38),F38>D38),1,0)+IF(AND(ISNUMBER(D41),ISNUMBER(F41),D41>F41),1,0)+IF(AND(ISNUMBER(D43),ISNUMBER(F43),D43>F43),1,0) -> 0 | N31: =IF(AND(ISNUMBER(F38),ISNUMBER(D38),F38=D38),1,0)+IF(AND(ISNUMBER(D41),ISNUMBER(F41),D41=F41),1,0)+IF(AND(ISNUMBER(D43),ISNUMBER(F43),D43=F43),1,0) -> 0 | O31: =IF(AND(ISNUMBER(F38),ISNUMBER(D38),F38<D38),1,0)+IF(AND(ISNUMBER(D41),ISNUMBER(F41),D41<F41),1,0)+IF(AND(ISNUMBER(D43),ISNUMBER(F43),D43<F43),1,0) -> 0 | P31: =IF(ISNUMBER(F38),F38,0)+IF(ISNUMBER(D41),D41,0)+IF(ISNUMBER(D43),D43,0) -> 0 | Q31: =IF(ISNUMBER(D38),D38,0)+IF(ISNUMBER(F41),F41,0)+IF(ISNUMBER(F43),F43,0) -> 0 | R31: =P31-Q31 -> 0 | S31: =M31*3+N31 -> 0 | T31: =S31*1000000 + (R31+100)*1000 + P31 + (ROW()/10000) -> 100000
C32: Estados Unidos | E32: - | G32: Australia | H32: =IF(AND(ISNUMBER(D32),ISNUMBER(F32)),"Ok","") | J32: E | K32: Costa de Marfil | L32: =IF(ISNUMBER(D39),1,0)+IF(ISNUMBER(F40),1,0)+IF(ISNUMBER(F43),1,0) -> 0 | M32: =IF(AND(ISNUMBER(D39),ISNUMBER(F39),D39>F39),1,0)+IF(AND(ISNUMBER(F40),ISNUMBER(D40),F40>D40),1,0)+IF(AND(ISNUMBER(F43),ISNUMBER(D43),F43>D43),1,0) -> 0 | N32: =IF(AND(ISNUMBER(D39),ISNUMBER(F39),D39=F39),1,0)+IF(AND(ISNUMBER(F40),ISNUMBER(D40),F40=D40),1,0)+IF(AND(ISNUMBER(F43),ISNUMBER(D43),F43=D43),1,0) -> 0 | O32: =IF(AND(ISNUMBER(D39),ISNUMBER(F39),D39<F39),1,0)+IF(AND(ISNUMBER(F40),ISNUMBER(D40),F40<D40),1,0)+IF(AND(ISNUMBER(F43),ISNUMBER(D43),F43<D43),1,0) -> 0 | P32: =IF(ISNUMBER(D39),D39,0)+IF(ISNUMBER(F40),F40,0)+IF(ISNUMBER(F43),F43,0) -> 0 | Q32: =IF(ISNUMBER(F39),F39,0)+IF(ISNUMBER(D40),D40,0)+IF(ISNUMBER(D43),D43,0) -> 0 | R32: =P32-Q32 -> 0 | S32: =M32*3+N32 -> 0 | T32: =S32*1000000 + (R32+100)*1000 + P32 + (ROW()/10000) -> 100000
C33: Paraguay | E33: - | G33: Turquía | H33: =IF(AND(ISNUMBER(D33),ISNUMBER(F33)),"Ok","") | J33: E | K33: Ecuador | L33: =IF(ISNUMBER(F39),1,0)+IF(ISNUMBER(F41),1,0)+IF(ISNUMBER(D42),1,0) -> 0 | M33: =IF(AND(ISNUMBER(F39),ISNUMBER(D39),F39>D39),1,0)+IF(AND(ISNUMBER(F41),ISNUMBER(D41),F41>D41),1,0)+IF(AND(ISNUMBER(D42),ISNUMBER(F42),D42>F42),1,0) -> 0 | N33: =IF(AND(ISNUMBER(F39),ISNUMBER(D39),F39=D39),1,0)+IF(AND(ISNUMBER(F41),ISNUMBER(D41),F41=D41),1,0)+IF(AND(ISNUMBER(D42),ISNUMBER(F42),D42=F42),1,0) -> 0 | O33: =IF(AND(ISNUMBER(F39),ISNUMBER(D39),F39<D39),1,0)+IF(AND(ISNUMBER(F41),ISNUMBER(D41),F41<D41),1,0)+IF(AND(ISNUMBER(D42),ISNUMBER(F42),D42<F42),1,0) -> 0 | P33: =IF(ISNUMBER(F39),F39,0)+IF(ISNUMBER(F41),F41,0)+IF(ISNUMBER(D42),D42,0) -> 0 | Q33: =IF(ISNUMBER(D39),D39,0)+IF(ISNUMBER(D41),D41,0)+IF(ISNUMBER(F42),F42,0) -> 0 | R33: =P33-Q33 -> 0 | S33: =M33*3+N33 -> 0 | T33: =S33*1000000 + (R33+100)*1000 + P33 + (ROW()/10000) -> 100000
C34: Turquía | E34: - | G34: Estados Unidos | H34: =IF(AND(ISNUMBER(D34),ISNUMBER(F34)),"Ok","")
C35: Paraguay | E35: - | G35: Australia | H35: =IF(AND(ISNUMBER(D35),ISNUMBER(F35)),"Ok","") | J35: CLASIFICACIÓN GRUPO F
J36: F | K36: Países Bajos | L36: =IF(ISNUMBER(D46),1,0)+IF(ISNUMBER(D48),1,0)+IF(ISNUMBER(F50),1,0) -> 0 | M36: =IF(AND(ISNUMBER(D46),ISNUMBER(F46),D46>F46),1,0)+IF(AND(ISNUMBER(D48),ISNUMBER(F48),D48>F48),1,0)+IF(AND(ISNUMBER(F50),ISNUMBER(D50),F50>D50),1,0) -> 0 | N36: =IF(AND(ISNUMBER(D46),ISNUMBER(F46),D46=F46),1,0)+IF(AND(ISNUMBER(D48),ISNUMBER(F48),D48=F48),1,0)+IF(AND(ISNUMBER(F50),ISNUMBER(D50),F50=D50),1,0) -> 0 | O36: =IF(AND(ISNUMBER(D46),ISNUMBER(F46),D46<F46),1,0)+IF(AND(ISNUMBER(D48),ISNUMBER(F48),D48<F48),1,0)+IF(AND(ISNUMBER(F50),ISNUMBER(D50),F50<D50),1,0) -> 0 | P36: =IF(ISNUMBER(D46),D46,0)+IF(ISNUMBER(D48),D48,0)+IF(ISNUMBER(F50),F50,0) -> 0 | Q36: =IF(ISNUMBER(F46),F46,0)+IF(ISNUMBER(F48),F48,0)+IF(ISNUMBER(D50),D50,0) -> 0 | R36: =P36-Q36 -> 0 | S36: =M36*3+N36 -> 0 | T36: =S36*1000000 + (R36+100)*1000 + P36 + (ROW()/10000) -> 100000
A37: GRUPO E | J37: F | K37: Japón | L37: =IF(ISNUMBER(F46),1,0)+IF(ISNUMBER(D49),1,0)+IF(ISNUMBER(D51),1,0) -> 0 | M37: =IF(AND(ISNUMBER(F46),ISNUMBER(D46),F46>D46),1,0)+IF(AND(ISNUMBER(D49),ISNUMBER(F49),D49>F49),1,0)+IF(AND(ISNUMBER(D51),ISNUMBER(F51),D51>F51),1,0) -> 0 | N37: =IF(AND(ISNUMBER(F46),ISNUMBER(D46),F46=D46),1,0)+IF(AND(ISNUMBER(D49),ISNUMBER(F49),D49=F49),1,0)+IF(AND(ISNUMBER(D51),ISNUMBER(F51),D51=F51),1,0) -> 0 | O37: =IF(AND(ISNUMBER(F46),ISNUMBER(D46),F46<D46),1,0)+IF(AND(ISNUMBER(D49),ISNUMBER(F49),D49<F49),1,0)+IF(AND(ISNUMBER(D51),ISNUMBER(F51),D51<F51),1,0) -> 0 | P37: =IF(ISNUMBER(F46),F46,0)+IF(ISNUMBER(D49),D49,0)+IF(ISNUMBER(D51),D51,0) -> 0 | Q37: =IF(ISNUMBER(D46),D46,0)+IF(ISNUMBER(F49),F49,0)+IF(ISNUMBER(F51),F51,0) -> 0 | R37: =P37-Q37 -> 0 | S37: =M37*3+N37 -> 0 | T37: =S37*1000000 + (R37+100)*1000 + P37 + (ROW()/10000) -> 100000
C38: Alemania | E38: - | G38: Curaçao | H38: =IF(AND(ISNUMBER(D38),ISNUMBER(F38)),"Ok","") | J38: F | K38: Suecia | L38: =IF(ISNUMBER(D47),1,0)+IF(ISNUMBER(F48),1,0)+IF(ISNUMBER(F51),1,0) -> 0 | M38: =IF(AND(ISNUMBER(D47),ISNUMBER(F47),D47>F47),1,0)+IF(AND(ISNUMBER(F48),ISNUMBER(D48),F48>D48),1,0)+IF(AND(ISNUMBER(F51),ISNUMBER(D51),F51>D51),1,0) -> 0 | N38: =IF(AND(ISNUMBER(D47),ISNUMBER(F47),D47=F47),1,0)+IF(AND(ISNUMBER(F48),ISNUMBER(D48),F48=D48),1,0)+IF(AND(ISNUMBER(F51),ISNUMBER(D51),F51=D51),1,0) -> 0 | O38: =IF(AND(ISNUMBER(D47),ISNUMBER(F47),D47<F47),1,0)+IF(AND(ISNUMBER(F48),ISNUMBER(D48),F48<D48),1,0)+IF(AND(ISNUMBER(F51),ISNUMBER(D51),F51<D51),1,0) -> 0 | P38: =IF(ISNUMBER(D47),D47,0)+IF(ISNUMBER(F48),F48,0)+IF(ISNUMBER(F51),F51,0) -> 0 | Q38: =IF(ISNUMBER(F47),F47,0)+IF(ISNUMBER(D48),D48,0)+IF(ISNUMBER(D51),D51,0) -> 0 | R38: =P38-Q38 -> 0 | S38: =M38*3+N38 -> 0 | T38: =S38*1000000 + (R38+100)*1000 + P38 + (ROW()/10000) -> 100000
C39: Costa de Marfil | E39: - | G39: Ecuador | H39: =IF(AND(ISNUMBER(D39),ISNUMBER(F39)),"Ok","") | J39: F | K39: Túnez | L39: =IF(ISNUMBER(F47),1,0)+IF(ISNUMBER(F49),1,0)+IF(ISNUMBER(D50),1,0) -> 0 | M39: =IF(AND(ISNUMBER(F47),ISNUMBER(D47),F47>D47),1,0)+IF(AND(ISNUMBER(F49),ISNUMBER(D49),F49>D49),1,0)+IF(AND(ISNUMBER(D50),ISNUMBER(F50),D50>F50),1,0) -> 0 | N39: =IF(AND(ISNUMBER(F47),ISNUMBER(D47),F47=D47),1,0)+IF(AND(ISNUMBER(F49),ISNUMBER(D49),F49=D49),1,0)+IF(AND(ISNUMBER(D50),ISNUMBER(F50),D50=F50),1,0) -> 0 | O39: =IF(AND(ISNUMBER(F47),ISNUMBER(D47),F47<D47),1,0)+IF(AND(ISNUMBER(F49),ISNUMBER(D49),F49<D49),1,0)+IF(AND(ISNUMBER(D50),ISNUMBER(F50),D50<F50),1,0) -> 0 | P39: =IF(ISNUMBER(F47),F47,0)+IF(ISNUMBER(F49),F49,0)+IF(ISNUMBER(D50),D50,0) -> 0 | Q39: =IF(ISNUMBER(D47),D47,0)+IF(ISNUMBER(D49),D49,0)+IF(ISNUMBER(F50),F50,0) -> 0 | R39: =P39-Q39 -> 0 | S39: =M39*3+N39 -> 0 | T39: =S39*1000000 + (R39+100)*1000 + P39 + (ROW()/10000) -> 100000
C40: Alemania | E40: - | G40: Costa de Marfil | H40: =IF(AND(ISNUMBER(D40),ISNUMBER(F40)),"Ok","")
C41: Curaçao | E41: - | G41: Ecuador | H41: =IF(AND(ISNUMBER(D41),ISNUMBER(F41)),"Ok","") | J41: CLASIFICACIÓN GRUPO G
C42: Ecuador | E42: - | G42: Alemania | H42: =IF(AND(ISNUMBER(D42),ISNUMBER(F42)),"Ok","") | J42: G | K42: Bélgica | L42: =IF(ISNUMBER(D54),1,0)+IF(ISNUMBER(D56),1,0)+IF(ISNUMBER(F58),1,0) -> 0 | M42: =IF(AND(ISNUMBER(D54),ISNUMBER(F54),D54>F54),1,0)+IF(AND(ISNUMBER(D56),ISNUMBER(F56),D56>F56),1,0)+IF(AND(ISNUMBER(F58),ISNUMBER(D58),F58>D58),1,0) -> 0 | N42: =IF(AND(ISNUMBER(D54),ISNUMBER(F54),D54=F54),1,0)+IF(AND(ISNUMBER(D56),ISNUMBER(F56),D56=F56),1,0)+IF(AND(ISNUMBER(F58),ISNUMBER(D58),F58=D58),1,0) -> 0 | O42: =IF(AND(ISNUMBER(D54),ISNUMBER(F54),D54<F54),1,0)+IF(AND(ISNUMBER(D56),ISNUMBER(F56),D56<F56),1,0)+IF(AND(ISNUMBER(F58),ISNUMBER(D58),F58<D58),1,0) -> 0 | P42: =IF(ISNUMBER(D54),D54,0)+IF(ISNUMBER(D56),D56,0)+IF(ISNUMBER(F58),F58,0) -> 0 | Q42: =IF(ISNUMBER(F54),F54,0)+IF(ISNUMBER(F56),F56,0)+IF(ISNUMBER(D58),D58,0) -> 0 | R42: =P42-Q42 -> 0 | S42: =M42*3+N42 -> 0 | T42: =S42*1000000 + (R42+100)*1000 + P42 + (ROW()/10000) -> 100000
C43: Curaçao | E43: - | G43: Costa de Marfil | H43: =IF(AND(ISNUMBER(D43),ISNUMBER(F43)),"Ok","") | J43: G | K43: Egipto | L43: =IF(ISNUMBER(F54),1,0)+IF(ISNUMBER(D57),1,0)+IF(ISNUMBER(D59),1,0) -> 0 | M43: =IF(AND(ISNUMBER(F54),ISNUMBER(D54),F54>D54),1,0)+IF(AND(ISNUMBER(D57),ISNUMBER(F57),D57>F57),1,0)+IF(AND(ISNUMBER(D59),ISNUMBER(F59),D59>F59),1,0) -> 0 | N43: =IF(AND(ISNUMBER(F54),ISNUMBER(D54),F54=D54),1,0)+IF(AND(ISNUMBER(D57),ISNUMBER(F57),D57=F57),1,0)+IF(AND(ISNUMBER(D59),ISNUMBER(F59),D59=F59),1,0) -> 0 | O43: =IF(AND(ISNUMBER(F54),ISNUMBER(D54),F54<D54),1,0)+IF(AND(ISNUMBER(D57),ISNUMBER(F57),D57<F57),1,0)+IF(AND(ISNUMBER(D59),ISNUMBER(F59),D59<F59),1,0) -> 0 | P43: =IF(ISNUMBER(F54),F54,0)+IF(ISNUMBER(D57),D57,0)+IF(ISNUMBER(D59),D59,0) -> 0 | Q43: =IF(ISNUMBER(D54),D54,0)+IF(ISNUMBER(F57),F57,0)+IF(ISNUMBER(F59),F59,0) -> 0 | R43: =P43-Q43 -> 0 | S43: =M43*3+N43 -> 0 | T43: =S43*1000000 + (R43+100)*1000 + P43 + (ROW()/10000) -> 100000
...

Sheet Backend
A1: GRUPO | B1: EQUIPO | C1: SCORE | D1: RANK GRUPO | F1: PRIMEROS Y SEGUNDOS | G1: SCORE GLOBAL | I1: TERCEROS | J1: SCORE TERCEROS | L1: TOP 24 (1ros y 2dos) | M1: TOP 8 (Mejores 3ros) | O1: CLASIFICADOS OFICIALES (32)
A2: =Grupos!J6 -> A | B2: =Grupos!K6 -> México | C2: =Grupos!T6 -> 100000 | D2: =RANK(C2, Grupos!$T$6:$T$9) -> 4 | F2: =IF(D2<=2, B2, "") | G2: =IF(D2<=2, C2, -1) -> -1 | I2: =IF(D2=3, B2, "") | J2: =IF(D2=3, C2, -1) -> -1 | L2: =INDEX(F$2:F$49, MATCH(LARGE(G$2:G$49, 1), G$2:G$49, 0)) -> Panamá | M2: =INDEX(I$2:I$49, MATCH(LARGE(J$2:J$49, 1), J$2:J$49, 0)) -> Croacia | O2: =L2 -> Panamá
A3: =Grupos!J7 -> A | B3: =Grupos!K7 -> Sudáfrica | C3: =Grupos!T7 -> 100000 | D3: =RANK(C3, Grupos!$T$6:$T$9) -> 3 | F3: =IF(D3<=2, B3, "") | G3: =IF(D3<=2, C3, -1) -> -1 | I3: =IF(D3=3, B3, "") -> Sudáfrica | J3: =IF(D3=3, C3, -1) -> 100000 | L3: =INDEX(F$2:F$49, MATCH(LARGE(G$2:G$49, 2), G$2:G$49, 0)) -> Ghana | M3: =INDEX(I$2:I$49, MATCH(LARGE(J$2:J$49, 2), J$2:J$49, 0)) -> RD Congo | O3: =L3 -> Ghana
A4: =Grupos!J8 -> A | B4: =Grupos!K8 -> Corea del Sur | C4: =Grupos!T8 -> 100000 | D4: =RANK(C4, Grupos!$T$6:$T$9) -> 2 | F4: =IF(D4<=2, B4, "") -> Corea del Sur | G4: =IF(D4<=2, C4, -1) -> 100000 | I4: =IF(D4=3, B4, "") | J4: =IF(D4=3, C4, -1) -> -1 | L4: =INDEX(F$2:F$49, MATCH(LARGE(G$2:G$49, 3), G$2:G$49, 0)) -> Colombia | M4: =INDEX(I$2:I$49, MATCH(LARGE(J$2:J$49, 3), J$2:J$49, 0)) -> Argelia | O4: =L4 -> Colombia
A5: =Grupos!J9 -> A | B5: =Grupos!K9 -> Chequia | C5: =Grupos!T9 -> 100000 | D5: =RANK(C5, Grupos!$T$6:$T$9) -> 1 | F5: =IF(D5<=2, B5, "") -> Chequia | G5: =IF(D5<=2, C5, -1) -> 100000 | I5: =IF(D5=3, B5, "") | J5: =IF(D5=3, C5, -1) -> -1 | L5: =INDEX(F$2:F$49, MATCH(LARGE(G$2:G$49, 4), G$2:G$49, 0)) -> Uzbekistán | M5: =INDEX(I$2:I$49, MATCH(LARGE(J$2:J$49, 4), J$2:J$49, 0)) -> Senegal | O5: =L5 -> Uzbekistán
A6: =Grupos!J12 -> B | B6: =Grupos!K12 -> Canadá | C6: =Grupos!T12 -> 100000 | D6: =RANK(C6, Grupos!$T$12:$T$15) -> 4 | F6: =IF(D6<=2, B6, "") | G6: =IF(D6<=2, C6, -1) -> -1 | I6: =IF(D6=3, B6, "") | J6: =IF(D6=3, C6, -1) -> -1 | L6: =INDEX(F$2:F$49, MATCH(LARGE(G$2:G$49, 5), G$2:G$49, 0)) -> Jordania | M6: =INDEX(I$2:I$49, MATCH(LARGE(J$2:J$49, 5), J$2:J$49, 0)) -> Cabo Verde | O6: =L6 -> Jordania
A7: =Grupos!J13 -> B | B7: =Grupos!K13 -> Bosnia y Herze. | C7: =Grupos!T13 -> 100000 | D7: =RANK(C7, Grupos!$T$12:$T$15) -> 3 | F7: =IF(D7<=2, B7, "") | G7: =IF(D7<=2, C7, -1) -> -1 | I7: =IF(D7=3, B7, "") -> Bosnia y Herze. | J7: =IF(D7=3, C7, -1) -> 100000 | L7: =INDEX(F$2:F$49, MATCH(LARGE(G$2:G$49, 6), G$2:G$49, 0)) -> Austria | M7: =INDEX(I$2:I$49, MATCH(LARGE(J$2:J$49, 6), J$2:J$49, 0)) -> Egipto | O7: =L7 -> Austria
A8: =Grupos!J14 -> B | B8: =Grupos!K14 -> Qatar | C8: =Grupos!T14 -> 100000 | D8: =RANK(C8, Grupos!$T$12:$T$15) -> 2 | F8: =IF(D8<=2, B8, "") -> Qatar | G8: =IF(D8<=2, C8, -1) -> 100000 | I8: =IF(D8=3, B8, "") | J8: =IF(D8=3, C8, -1) -> -1 | L8: =INDEX(F$2:F$49, MATCH(LARGE(G$2:G$49, 7), G$2:G$49, 0)) -> Noruega | M8: =INDEX(I$2:I$49, MATCH(LARGE(J$2:J$49, 7), J$2:J$49, 0)) -> Japón | O8: =L8 -> Noruega
A9: =Grupos!J15 -> B | B9: =Grupos!K15 -> Suiza | C9: =Grupos!T15 -> 100000 | D9: =RANK(C9, Grupos!$T$12:$T$15) -> 1 | F9: =IF(D9<=2, B9, "") -> Suiza | G9: =IF(D9<=2, C9, -1) -> 100000 | I9: =IF(D9=3, B9, "") | J9: =IF(D9=3, C9, -1) -> -1 | L9: =INDEX(F$2:F$49, MATCH(LARGE(G$2:G$49, 8), G$2:G$49, 0)) -> Irak | M9: =INDEX(I$2:I$49, MATCH(LARGE(J$2:J$49, 8), J$2:J$49, 0)) -> Curaçao | O9: =L9 -> Irak
A10: =Grupos!J18 -> C | B10: =Grupos!K18 -> Brasil | C10: =Grupos!T18 -> 100000 | D10: =RANK(C10, Grupos!$T$18:$T$21) -> 4 | F10: =IF(D10<=2, B10, "") | G10: =IF(D10<=2, C10, -1) -> -1 | I10: =IF(D10=3, B10, "") | J10: =IF(D10=3, C10, -1) -> -1 | L10: =INDEX(F$2:F$49, MATCH(LARGE(G$2:G$49, 9), G$2:G$49, 0)) -> Uruguay | O10: =L10 -> Uruguay
A11: =Grupos!J19 -> C | B11: =Grupos!K19 -> Marruecos | C11: =Grupos!T19 -> 100000 | D11: =RANK(C11, Grupos!$T$18:$T$21) -> 3 | F11: =IF(D11<=2, B11, "") | G11: =IF(D11<=2, C11, -1) -> -1 | I11: =IF(D11=3, B11, "") -> Marruecos | J11: =IF(D11=3, C11, -1) -> 100000 | L11: =INDEX(F$2:F$49, MATCH(LARGE(G$2:G$49, 10), G$2:G$49, 0)) -> Arabia Saud. | O11: =L11 -> Arabia Saud.
A12: =Grupos!J20 -> C | B12: =Grupos!K20 -> Haití | C12: =Grupos!T20 -> 100000 | D12: =RANK(C12, Grupos!$T$18:$T$21) -> 2 | F12: =IF(D12<=2, B12, "") -> Haití | G12: =IF(D12<=2, C12, -1) -> 100000 | I12: =IF(D12=3, B12, "") | J12: =IF(D12=3, C12, -1) -> -1 | L12: =INDEX(F$2:F$49, MATCH(LARGE(G$2:G$49, 11), G$2:G$49, 0)) -> Nueva Zelanda | O12: =L12 -> Nueva Zelanda
A13: =Grupos!J21 -> C | B13: =Grupos!K21 -> Escocia | C13: =Grupos!T21 -> 100000 | D13: =RANK(C13, Grupos!$T$18:$T$21) -> 1 | F13: =IF(D13<=2, B13, "") -> Escocia | G13: =IF(D13<=2, C13, -1) -> 100000 | I13: =IF(D13=3, B13, "") | J13: =IF(D13=3, C13, -1) -> -1 | L13: =INDEX(F$2:F$49, MATCH(LARGE(G$2:G$49, 12), G$2:G$49, 0)) -> Irán | O13: =L13 -> Irán
A14: =Grupos!J24 -> D | B14: =Grupos!K24 -> Estados Unidos | C14: =Grupos!T24 -> 100000 | D14: =RANK(C14, Grupos!$T$24:$T$27) -> 4 | F14: =IF(D14<=2, B14, "") | G14: =IF(D14<=2, C14, -1) -> -1 | I14: =IF(D14=3, B14, "") | J14: =IF(D14=3, C14, -1) -> -1 | L14: =INDEX(F$2:F$49, MATCH(LARGE(G$2:G$49, 13), G$2:G$49, 0)) -> Túnez | O14: =L14 -> Túnez
A15: =Grupos!J25 -> D | B15: =Grupos!K25 -> Paraguay | C15: =Grupos!T25 -> 100000 | D15: =RANK(C15, Grupos!$T$24:$T$27) -> 3 | F15: =IF(D15<=2, B15, "") | G15: =IF(D15<=2, C15, -1) -> -1 | I15: =IF(D15=3, B15, "") -> Paraguay | J15: =IF(D15=3, C15, -1) -> 100000 | L15: =INDEX(F$2:F$49, MATCH(LARGE(G$2:G$49, 14), G$2:G$49, 0)) -> Suecia | O15: =L15 -> Suecia
A16: =Grupos!J26 -> D | B16: =Grupos!K26 -> Australia | C16: =Grupos!T26 -> 100000 | D16: =RANK(C16, Grupos!$T$24:$T$27) -> 2 | F16: =IF(D16<=2, B16, "") -> Australia | G16: =IF(D16<=2, C16, -1) -> 100000 | I16: =IF(D16=3, B16, "") | J16: =IF(D16=3, C16, -1) -> -1 | L16: =INDEX(F$2:F$49, MATCH(LARGE(G$2:G$49, 15), G$2:G$49, 0)) -> Ecuador | O16: =L16 -> Ecuador
A17: =Grupos!J27 -> D | B17: =Grupos!K27 -> Turquía | C17: =Grupos!T27 -> 100000 | D17: =RANK(C17, Grupos!$T$24:$T$27) -> 1 | F17: =IF(D17<=2, B17, "") -> Turquía | G17: =IF(D17<=2, C17, -1) -> 100000 | I17: =IF(D17=3, B17, "") | J17: =IF(D17=3, C17, -1) -> -1 | L17: =INDEX(F$2:F$49, MATCH(LARGE(G$2:G$49, 16), G$2:G$49, 0)) -> Costa de Marfil | O17: =L17 -> Costa de Marfil
A18: =Grupos!J30 -> E | B18: =Grupos!K30 -> Alemania | C18: =Grupos!T30 -> 100000 | D18: =RANK(C18, Grupos!$T$30:$T$33) -> 4 | F18: =IF(D18<=2, B18, "") | G18: =IF(D18<=2, C18, -1) -> -1 | I18: =IF(D18=3, B18, "") | J18: =IF(D18=3, C18, -1) -> -1 | L18: =INDEX(F$2:F$49, MATCH(LARGE(G$2:G$49, 17), G$2:G$49, 0)) -> Turquía | O18: =L18 -> Turquía
A19: =Grupos!J31 -> E | B19: =Grupos!K31 -> Curaçao | C19: =Grupos!T31 -> 100000 | D19: =RANK(C19, Grupos!$T$30:$T$33) -> 3 | F19: =IF(D19<=2, B19, "") | G19: =IF(D19<=2, C19, -1) -> -1 | I19: =IF(D19=3, B19, "") -> Curaçao | J19: =IF(D19=3, C19, -1) -> 100000 | L19: =INDEX(F$2:F$49, MATCH(LARGE(G$2:G$49, 18), G$2:G$49, 0)) -> Australia | O19: =L19 -> Australia
A20: =Grupos!J32 -> E | B20: =Grupos!K32 -> Costa de Marfil | C20: =Grupos!T32 -> 100000 | D20: =RANK(C20, Grupos!$T$30:$T$33) -> 2 | F20: =IF(D20<=2, B20, "") -> Costa de Marfil | G20: =IF(D20<=2, C20, -1) -> 100000 | I20: =IF(D20=3, B20, "") | J20: =IF(D20=3, C20, -1) -> -1 | L20: =INDEX(F$2:F$49, MATCH(LARGE(G$2:G$49, 19), G$2:G$49, 0)) -> Escocia | O20: =L20 -> Escocia
A21: =Grupos!J33 -> E | B21: =Grupos!K33 -> Ecuador | C21: =Grupos!T33 -> 100000 | D21: =RANK(C21, Grupos!$T$30:$T$33) -> 1 | F21: =IF(D21<=2, B21, "") -> Ecuador | G21: =IF(D21<=2, C21, -1) -> 100000 | I21: =IF(D21=3, B21, "") | J21: =IF(D21=3, C21, -1) -> -1 | L21: =INDEX(F$2:F$49, MATCH(LARGE(G$2:G$49, 20), G$2:G$49, 0)) -> Haití | O21: =L21 -> Haití
A22: =Grupos!J36 -> F | B22: =Grupos!K36 -> Países Bajos | C22: =Grupos!T36 -> 100000 | D22: =RANK(C22, Grupos!$T$36:$T$39) -> 4 | F22: =IF(D22<=2, B22, "") | G22: =IF(D22<=2, C22, -1) -> -1 | I22: =IF(D22=3, B22, "") | J22: =IF(D22=3, C22, -1) -> -1 | L22: =INDEX(F$2:F$49, MATCH(LARGE(G$2:G$49, 21), G$2:G$49, 0)) -> Suiza | O22: =L22 -> Suiza
A23: =Grupos!J37 -> F | B23: =Grupos!K37 -> Japón | C23: =Grupos!T37 -> 100000 | D23: =RANK(C23, Grupos!$T$36:$T$39) -> 3 | F23: =IF(D23<=2, B23, "") | G23: =IF(D23<=2, C23, -1) -> -1 | I23: =IF(D23=3, B23, "") -> Japón | J23: =IF(D23=3, C23, -1) -> 100000 | L23: =INDEX(F$2:F$49, MATCH(LARGE(G$2:G$49, 22), G$2:G$49, 0)) -> Qatar | O23: =L23 -> Qatar
A24: =Grupos!J38 -> F | B24: =Grupos!K38 -> Suecia | C24: =Grupos!T38 -> 100000 | D24: =RANK(C24, Grupos!$T$36:$T$39) -> 2 | F24: =IF(D24<=2, B24, "") -> Suecia | G24: =IF(D24<=2, C24, -1) -> 100000 | I24: =IF(D24=3, B24, "") | J24: =IF(D24=3, C24, -1) -> -1 | L24: =INDEX(F$2:F$49, MATCH(LARGE(G$2:G$49, 23), G$2:G$49, 0)) -> Chequia | O24: =L24 -> Chequia
A25: =Grupos!J39 -> F | B25: =Grupos!K39 -> Túnez | C25: =Grupos!T39 -> 100000 | D25: =RANK(C25, Grupos!$T$36:$T$39) -> 1 | F25: =IF(D25<=2, B25, "") -> Túnez | G25: =IF(D25<=2, C25, -1) -> 100000 | I25: =IF(D25=3, B25, "") | J25: =IF(D25=3, C25, -1) -> -1 | L25: =INDEX(F$2:F$49, MATCH(LARGE(G$2:G$49, 24), G$2:G$49, 0)) -> Corea del Sur | O25: =L25 -> Corea del Sur
A26: =Grupos!J42 -> G | B26: =Grupos!K42 -> Bélgica | C26: =Grupos!T42 -> 100000 | D26: =RANK(C26, Grupos!$T$42:$T$45) -> 4 | F26: =IF(D26<=2, B26, "") | G26: =IF(D26<=2, C26, -1) -> -1 | I26: =IF(D26=3, B26, "") | J26: =IF(D26=3, C26, -1) -> -1 | O26: =M2 -> Croacia
A27: =Grupos!J43 -> G | B27: =Grupos!K43 -> Egipto | C27: =Grupos!T43 -> 100000 | D27: =RANK(C27, Grupos!$T$42:$T$45) -> 3 | F27: =IF(D27<=2, B27, "") | G27: =IF(D27<=2, C27, -1) -> -1 | I27: =IF(D27=3, B27, "") -> Egipto | J27: =IF(D27=3, C27, -1) -> 100000 | O27: =M3 -> RD Congo
A28: =Grupos!J44 -> G | B28: =Grupos!K44 -> Irán | C28: =Grupos!T44 -> 100000 | D28: =RANK(C28, Grupos!$T$42:$T$45) -> 2 | F28: =IF(D28<=2, B28, "") -> Irán | G28: =IF(D28<=2, C28, -1) -> 100000 | I28: =IF(D28=3, B28, "") | J28: =IF(D28=3, C28, -1) -> -1 | O28: =M4 -> Argelia
A29: =Grupos!J45 -> G | B29: =Grupos!K45 -> Nueva Zelanda | C29: =Grupos!T45 -> 100000 | D29: =RANK(C29, Grupos!$T$42:$T$45) -> 1 | F29: =IF(D29<=2, B29, "") -> Nueva Zelanda | G29: =IF(D29<=2, C29, -1) -> 100000 | I29: =IF(D29=3, B29, "") | J29: =IF(D29=3, C29, -1) -> -1 | O29: =M5 -> Senegal
A30: =Grupos!J48 -> H | B30: =Grupos!K48 -> España | C30: =Grupos!T48 -> 100000 | D30: =RANK(C30, Grupos!$T$48:$T$51) -> 4 | F30: =IF(D30<=2, B30, "") | G30: =IF(D30<=2, C30, -1) -> -1 | I30: =IF(D30=3, B30, "") | J30: =IF(D30=3, C30, -1) -> -1 | O30: =M6 -> Cabo Verde
A31: =Grupos!J49 -> H | B31: =Grupos!K49 -> Cabo Verde | C31: =Grupos!T49 -> 100000 | D31: =RANK(C31, Grupos!$T$48:$T$51) -> 3 | F31: =IF(D31<=2, B31, "") | G31: =IF(D31<=2, C31, -1) -> -1 | I31: =IF(D31=3, B31, "") -> Cabo Verde | J31: =IF(D31=3, C31, -1) -> 100000 | O31: =M7 -> Egipto
A32: =Grupos!J50 -> H | B32: =Grupos!K50 -> Arabia Saud. | C32: =Grupos!T50 -> 100000.01 | D32: =RANK(C32, Grupos!$T$48:$T$51) -> 2 | F32: =IF(D32<=2, B32, "") -> Arabia Saud. | G32: =IF(D32<=2, C32, -1) -> 100000.01 | I32: =IF(D32=3, B32, "") | J32: =IF(D32=3, C32, -1) -> -1 | O32: =M8 -> Japón
A33: =Grupos!J51 -> H | B33: =Grupos!K51 -> Uruguay | C33: =Grupos!T51 -> 100000.01 | D33: =RANK(C33, Grupos!$T$48:$T$51) -> 1 | F33: =IF(D33<=2, B33, "") -> Uruguay | G33: =IF(D33<=2, C33, -1) -> 100000.01 | I33: =IF(D33=3, B33, "") | J33: =IF(D33=3, C33, -1) -> -1 | O33: =M9 -> Curaçao
A34: =Grupos!J54 -> I | B34: =Grupos!K54 -> Francia | C34: =Grupos!T54 -> 100000.01 | D34: =RANK(C34, Grupos!$T$54:$T$57) -> 4 | F34: =IF(D34<=2, B34, "") | G34: =IF(D34<=2, C34, -1) -> -1 | I34: =IF(D34=3, B34, "") | J34: =IF(D34=3, C34, -1) -> -1
A35: =Grupos!J55 -> I | B35: =Grupos!K55 -> Senegal | C35: =Grupos!T55 -> 100000.01 | D35: =RANK(C35, Grupos!$T$54:$T$57) -> 3 | F35: =IF(D35<=2, B35, "") | G35: =IF(D35<=2, C35, -1) -> -1 | I35: =IF(D35=3, B35, "") -> Senegal | J35: =IF(D35=3, C35, -1) -> 100000.01
A36: =Grupos!J56 -> I | B36: =Grupos!K56 -> Irak | C36: =Grupos!T56 -> 100000.01 | D36: =RANK(C36, Grupos!$T$54:$T$57) -> 2 | F36: =IF(D36<=2, B36, "") -> Irak | G36: =IF(D36<=2, C36, -1) -> 100000.01 | I36: =IF(D36=3, B36, "") | J36: =IF(D36=3, C36, -1) -> -1
A37: =Grupos!J57 -> I | B37: =Grupos!K57 -> Noruega | C37: =Grupos!T57 -> 100000.01 | D37: =RANK(C37, Grupos!$T$54:$T$57) -> 1 | F37: =IF(D37<=2, B37, "") -> Noruega | G37: =IF(D37<=2, C37, -1) -> 100000.01 | I37: =IF(D37=3, B37, "") | J37: =IF(D37=3, C37, -1) -> -1
A38: =Grupos!J60 -> J | B38: =Grupos!K60 -> Argentina | C38: =Grupos!T60 -> 100000.01 | D38: =RANK(C38, Grupos!$T$60:$T$63) -> 4 | F38: =IF(D38<=2, B38, "") | G38: =IF(D38<=2, C38, -1) -> -1 | I38: =IF(D38=3, B38, "") | J38: =IF(D38=3, C38, -1) -> -1
A39: =Grupos!J61 -> J | B39: =Grupos!K61 -> Argelia | C39: =Grupos!T61 -> 100000.01 | D39: =RANK(C39, Grupos!$T$60:$T$63) -> 3 | F39: =IF(D39<=2, B39, "") | G39: =IF(D39<=2, C39, -1) -> -1 | I39: =IF(D39=3, B39, "") -> Argelia | J39: =IF(D39=3, C39, -1) -> 100000.01
A40: =Grupos!J62 -> J | B40: =Grupos!K62 -> Austria | C40: =Grupos!T62 -> 100000.01 | D40: =RANK(C40, Grupos!$T$60:$T$63) -> 2 | F40: =IF(D40<=2, B40, "") -> Austria | G40: =IF(D40<=2, C40, -1) -> 100000.01 | I40: =IF(D40=3, B40, "") | J40: =IF(D40=3, C40, -1) -> -1
...

Sheet Eliminatorias
A1: FASE FINAL (ELIMINACIÓN DIRECTA)
A4: DIECISEISAVOS DE FINAL (Ronda de 32)
A5: Partido | B5: Equipo A | C5: Goles | D5: vs | E5: Goles | F5: Equipo B | G5: Clasifica | H5: Estado
A6: 1/16 - P1 | B6: =IF(Backend!O2="","",Backend!O2) -> Panamá | D6: - | F6: =IF(Backend!O3="","",Backend!O3) -> Ghana | G6: =IF(AND(ISNUMBER(C6),ISNUMBER(E6)),IF(C6>E6,B6,F6),"")
A7: 1/16 - P2 | B7: =IF(Backend!O4="","",Backend!O4) -> Colombia | D7: - | F7: =IF(Backend!O5="","",Backend!O5) -> Uzbekistán | G7: =IF(AND(ISNUMBER(C7),ISNUMBER(E7)),IF(C7>E7,B7,F7),"")
A8: 1/16 - P3 | B8: =IF(Backend!O6="","",Backend!O6) -> Jordania | D8: - | F8: =IF(Backend!O7="","",Backend!O7) -> Austria | G8: =IF(AND(ISNUMBER(C8),ISNUMBER(E8)),IF(C8>E8,B8,F8),"")
A9: 1/16 - P4 | B9: =IF(Backend!O8="","",Backend!O8) -> Noruega | D9: - | F9: =IF(Backend!O9="","",Backend!O9) -> Irak | G9: =IF(AND(ISNUMBER(C9),ISNUMBER(E9)),IF(C9>E9,B9,F9),"")
A10: 1/16 - P5 | B10: =IF(Backend!O10="","",Backend!O10) -> Uruguay | D10: - | F10: =IF(Backend!O11="","",Backend!O11) -> Arabia Saud. | G10: =IF(AND(ISNUMBER(C10),ISNUMBER(E10)),IF(C10>E10,B10,F10),"")
A11: 1/16 - P6 | B11: =IF(Backend!O12="","",Backend!O12) -> Nueva Zelanda | D11: - | F11: =IF(Backend!O13="","",Backend!O13) -> Irán | G11: =IF(AND(ISNUMBER(C11),ISNUMBER(E11)),IF(C11>E11,B11,F11),"")
A12: 1/16 - P7 | B12: =IF(Backend!O14="","",Backend!O14) -> Túnez | D12: - | F12: =IF(Backend!O15="","",Backend!O15) -> Suecia | G12: =IF(AND(ISNUMBER(C12),ISNUMBER(E12)),IF(C12>E12,B12,F12),"")
A13: 1/16 - P8 | B13: =IF(Backend!O16="","",Backend!O16) -> Ecuador | D13: - | F13: =IF(Backend!O17="","",Backend!O17) -> Costa de Marfil | G13: =IF(AND(ISNUMBER(C13),ISNUMBER(E13)),IF(C13>E13,B13,F13),"")
A14: 1/16 - P9 | B14: =IF(Backend!O18="","",Backend!O18) -> Turquía | D14: - | F14: =IF(Backend!O19="","",Backend!O19) -> Australia | G14: =IF(AND(ISNUMBER(C14),ISNUMBER(E14)),IF(C14>E14,B14,F14),"")
A15: 1/16 - P10 | B15: =IF(Backend!O20="","",Backend!O20) -> Escocia | D15: - | F15: =IF(Backend!O21="","",Backend!O21) -> Haití | G15: =IF(AND(ISNUMBER(C15),ISNUMBER(E15)),IF(C15>E15,B15,F15),"")
A16: 1/16 - P11 | B16: =IF(Backend!O22="","",Backend!O22) -> Suiza | D16: - | F16: =IF(Backend!O23="","",Backend!O23) -> Qatar | G16: =IF(AND(ISNUMBER(C16),ISNUMBER(E16)),IF(C16>E16,B16,F16),"")
A17: 1/16 - P12 | B17: =IF(Backend!O24="","",Backend!O24) -> Chequia | D17: - | F17: =IF(Backend!O25="","",Backend!O25) -> Corea del Sur | G17: =IF(AND(ISNUMBER(C17),ISNUMBER(E17)),IF(C17>E17,B17,F17),"")
A18: 1/16 - P13 | B18: =IF(Backend!O26="","",Backend!O26) -> Croacia | D18: - | F18: =IF(Backend!O27="","",Backend!O27) -> RD Congo | G18: =IF(AND(ISNUMBER(C18),ISNUMBER(E18)),IF(C18>E18,B18,F18),"")
A19: 1/16 - P14 | B19: =IF(Backend!O28="","",Backend!O28) -> Argelia | D19: - | F19: =IF(Backend!O29="","",Backend!O29) -> Senegal | G19: =IF(AND(ISNUMBER(C19),ISNUMBER(E19)),IF(C19>E19,B19,F19),"")
A20: 1/16 - P15 | B20: =IF(Backend!O30="","",Backend!O30) -> Cabo Verde | D20: - | F20: =IF(Backend!O31="","",Backend!O31) -> Egipto | G20: =IF(AND(ISNUMBER(C20),ISNUMBER(E20)),IF(C20>E20,B20,F20),"")
A21: 1/16 - P16 | B21: =IF(Backend!O32="","",Backend!O32) -> Japón | D21: - | F21: =IF(Backend!O33="","",Backend!O33) -> Curaçao | G21: =IF(AND(ISNUMBER(C21),ISNUMBER(E21)),IF(C21>E21,B21,F21),"")
A23: OCTAVOS DE FINAL
A25: 1/8 - P1 | B25: =IF(G6="","",G6) | D25: - | F25: =IF(G7="","",G7) | G25: =IF(AND(ISNUMBER(C25),ISNUMBER(E25)),IF(C25>E25,B25,F25),"")
A26: 1/8 - P2 | B26: =IF(G8="","",G8) | D26: - | F26: =IF(G9="","",G9) | G26: =IF(AND(ISNUMBER(C26),ISNUMBER(E26)),IF(C26>E26,B26,F26),"")
A27: 1/8 - P3 | B27: =IF(G10="","",G10) | D27: - | F27: =IF(G11="","",G11) | G27: =IF(AND(ISNUMBER(C27),ISNUMBER(E27)),IF(C27>E27,B27,F27),"")
A28: 1/8 - P4 | B28: =IF(G12="","",G12) | D28: - | F28: =IF(G13="","",G13) | G28: =IF(AND(ISNUMBER(C28),ISNUMBER(E28)),IF(C28>E28,B28,F28),"")
A29: 1/8 - P5 | B29: =IF(G14="","",G14) | D29: - | F29: =IF(G15="","",G15) | G29: =IF(AND(ISNUMBER(C29),ISNUMBER(E29)),IF(C29>E29,B29,F29),"")
A30: 1/8 - P6 | B30: =IF(G16="","",G16) | D30: - | F30: =IF(G17="","",G17) | G30: =IF(AND(ISNUMBER(C30),ISNUMBER(E30)),IF(C30>E30,B30,F30),"")
A31: 1/8 - P7 | B31: =IF(G18="","",G18) | D31: - | F31: =IF(G19="","",G19) | G31: =IF(AND(ISNUMBER(C31),ISNUMBER(E31)),IF(C31>E31,B31,F31),"")
A32: 1/8 - P8 | B32: =IF(G20="","",G20) | D32: - | F32: =IF(G21="","",G21) | G32: =IF(AND(ISNUMBER(C32),ISNUMBER(E32)),IF(C32>E32,B32,F32),"")
A35: CUARTOS DE FINAL
A36: Partido | B36: Equipo A | C36: Goles | D36: vs | E36: Goles | F36: Equipo B | G36: Clasifica | H36: Estado
A37: 1/4 - P1 | B37: =IF(G25="","",G25) | D37: - | F37: =IF(G26="","",G26) | G37: =IF(AND(ISNUMBER(C37),ISNUMBER(E37)),IF(C37>E37,B37,F37),"")
A38: 1/4 - P2 | B38: =IF(G27="","",G27) | D38: - | F38: =IF(G28="","",G28) | G38: =IF(AND(ISNUMBER(C38),ISNUMBER(E38)),IF(C38>E38,B38,F38),"")
A39: 1/4 - P3 | B39: =IF(G29="","",G29) | D39: - | F39: =IF(G30="","",G30) | G39: =IF(AND(ISNUMBER(C39),ISNUMBER(E39)),IF(C39>E39,B39,F39),"")
A40: 1/4 - P4 | B40: =IF(G31="","",G31) | D40: - | F40: =IF(G32="","",G32) | G40: =IF(AND(ISNUMBER(C40),ISNUMBER(E40)),IF(C40>E40,B40,F40),"")
A43: SEMIFINALES
A44: Partido | B44: Equipo A | C44: Goles | D44: vs | E44: Goles | F44: Equipo B | G44: Clasifica | H44: Estado
A45: Semi - P1 | B45: =IF(G37="","",G37) | D45: - | F45: =IF(G38="","",G38) | G45: =IF(AND(ISNUMBER(C45),ISNUMBER(E45)),IF(C45>E45,B45,F45),"")
A46: Semi - P2 | B46: =IF(G39="","",G39) | D46: - | F46: =IF(G40="","",G40) | G46: =IF(AND(ISNUMBER(C46),ISNUMBER(E46)),IF(C46>E46,B46,F46),"")
A49: PARTIDO POR EL TERCER LUGAR
A50: Partido | B50: Equipo A | C50: Goles | D50: vs | E50: Goles | F50: Equipo B | G50: Clasifica | H50: Estado
...
