Workbook

Sheet Instrucciones
A1: QUINIELA MUNDIAL DE FÚTBOL 2026 - 100% AUTOMATIZADA
A4: CÓMO FUNCIONA:
A5: 1. Pestaña 'Grupos': Ingresa los resultados. Las tablas se calculan en tiempo real.
A6: 2. Pestaña 'Eliminatorias': Al ir llenando, verás cómo los nombres se auto-completan gracias a la corrección del motor.
A7: 3. Puedes empezar a llenar y los líderes de cada grupo aparecerán de inmediato.
B9: Salvador Velasco Téllez

Sheet Grupos
A1: PARTIDOS DE GRUPOS | J1: TABLAS DE POSICIONES (AUTOMÁTICAS)
A4: ID | B4: Grupo | C4: Equipo 1 | D4: Goles | E4: vs | F4: Goles | G4: Equipo 2 | H4: Estado | J4: Grupo | K4: Equipo | L4: PJ | M4: PG | N4: PE | O4: PP | P4: GF | Q4: GC | R4: DIF | S4: PTS | T4: SCORE TIEBREAK
A5: GRUPO A | J5: CLASIFICACIÓN GRUPO A
C6: México | D6: 2 | E6: - | F6: 0 | G6: Sudáfrica | H6: =IF(AND(ISNUMBER(D6),ISNUMBER(F6)),"Ok","") | J6: A | K6: México | L6: =IF(ISNUMBER(D6),1,0)+IF(ISNUMBER(D8),1,0)+IF(ISNUMBER(F10),1,0) | M6: =IF(AND(ISNUMBER(D6),ISNUMBER(F6),D6>F6),1,0)+IF(AND(ISNUMBER(D8),ISNUMBER(F8),D8>F8),1,0)+IF(AND(ISNUMBER(F10),ISNUMBER(D10),F10>D10),1,0) | N6: =IF(AND(ISNUMBER(D6),ISNUMBER(F6),D6=F6),1,0)+IF(AND(ISNUMBER(D8),ISNUMBER(F8),D8=F8),1,0)+IF(AND(ISNUMBER(F10),ISNUMBER(D10),F10=D10),1,0) | O6: =IF(AND(ISNUMBER(D6),ISNUMBER(F6),D6<F6),1,0)+IF(AND(ISNUMBER(D8),ISNUMBER(F8),D8<F8),1,0)+IF(AND(ISNUMBER(F10),ISNUMBER(D10),F10<D10),1,0) | P6: =IF(ISNUMBER(D6),D6,0)+IF(ISNUMBER(D8),D8,0)+IF(ISNUMBER(F10),F10,0) | Q6: =IF(ISNUMBER(F6),F6,0)+IF(ISNUMBER(F8),F8,0)+IF(ISNUMBER(D10),D10,0) | R6: =P6-Q6 | S6: =M6*3+N6 | T6: =S6*100000000 + (R6+100)*100000 + P6*1000 + IFERROR(VLOOKUP(K6, RankingFIFA!$A$1:$B$48, 2, FALSE), 0)
C7: Corea del Sur | D7: 1 | E7: - | F7: 1 | G7: Chequia | H7: =IF(AND(ISNUMBER(D7),ISNUMBER(F7)),"Ok","") | J7: A | K7: Sudáfrica | L7: =IF(ISNUMBER(F6),1,0)+IF(ISNUMBER(D9),1,0)+IF(ISNUMBER(D11),1,0) | M7: =IF(AND(ISNUMBER(F6),ISNUMBER(D6),F6>D6),1,0)+IF(AND(ISNUMBER(D9),ISNUMBER(F9),D9>F9),1,0)+IF(AND(ISNUMBER(D11),ISNUMBER(F11),D11>F11),1,0) | N7: =IF(AND(ISNUMBER(F6),ISNUMBER(D6),F6=D6),1,0)+IF(AND(ISNUMBER(D9),ISNUMBER(F9),D9=F9),1,0)+IF(AND(ISNUMBER(D11),ISNUMBER(F11),D11=F11),1,0) | O7: =IF(AND(ISNUMBER(F6),ISNUMBER(D6),F6<D6),1,0)+IF(AND(ISNUMBER(D9),ISNUMBER(F9),D9<F9),1,0)+IF(AND(ISNUMBER(D11),ISNUMBER(F11),D11<F11),1,0) | P7: =IF(ISNUMBER(F6),F6,0)+IF(ISNUMBER(D9),D9,0)+IF(ISNUMBER(D11),D11,0) | Q7: =IF(ISNUMBER(D6),D6,0)+IF(ISNUMBER(F9),F9,0)+IF(ISNUMBER(F11),F11,0) | R7: =P7-Q7 | S7: =M7*3+N7 | T7: =S7*100000000 + (R7+100)*100000 + P7*1000 + IFERROR(VLOOKUP(K7, RankingFIFA!$A$1:$B$48, 2, FALSE), 0)
C8: México | D8: 3 | E8: - | F8: 1 | G8: Corea del Sur | H8: =IF(AND(ISNUMBER(D8),ISNUMBER(F8)),"Ok","") | J8: A | K8: Corea del Sur | L8: =IF(ISNUMBER(D7),1,0)+IF(ISNUMBER(F8),1,0)+IF(ISNUMBER(F11),1,0) | M8: =IF(AND(ISNUMBER(D7),ISNUMBER(F7),D7>F7),1,0)+IF(AND(ISNUMBER(F8),ISNUMBER(D8),F8>D8),1,0)+IF(AND(ISNUMBER(F11),ISNUMBER(D11),F11>D11),1,0) | N8: =IF(AND(ISNUMBER(D7),ISNUMBER(F7),D7=F7),1,0)+IF(AND(ISNUMBER(F8),ISNUMBER(D8),F8=D8),1,0)+IF(AND(ISNUMBER(F11),ISNUMBER(D11),F11=D11),1,0) | O8: =IF(AND(ISNUMBER(D7),ISNUMBER(F7),D7<F7),1,0)+IF(AND(ISNUMBER(F8),ISNUMBER(D8),F8<D8),1,0)+IF(AND(ISNUMBER(F11),ISNUMBER(D11),F11<D11),1,0) | P8: =IF(ISNUMBER(D7),D7,0)+IF(ISNUMBER(F8),F8,0)+IF(ISNUMBER(F11),F11,0) | Q8: =IF(ISNUMBER(F7),F7,0)+IF(ISNUMBER(D8),D8,0)+IF(ISNUMBER(D11),D11,0) | R8: =P8-Q8 | S8: =M8*3+N8 | T8: =S8*100000000 + (R8+100)*100000 + P8*1000 + IFERROR(VLOOKUP(K8, RankingFIFA!$A$1:$B$48, 2, FALSE), 0)
C9: Sudáfrica | D9: 1 | E9: - | F9: 2 | G9: Chequia | H9: =IF(AND(ISNUMBER(D9),ISNUMBER(F9)),"Ok","") | J9: A | K9: Chequia | L9: =IF(ISNUMBER(F7),1,0)+IF(ISNUMBER(F9),1,0)+IF(ISNUMBER(D10),1,0) | M9: =IF(AND(ISNUMBER(F7),ISNUMBER(D7),F7>D7),1,0)+IF(AND(ISNUMBER(F9),ISNUMBER(D9),F9>D9),1,0)+IF(AND(ISNUMBER(D10),ISNUMBER(F10),D10>F10),1,0) | N9: =IF(AND(ISNUMBER(F7),ISNUMBER(D7),F7=D7),1,0)+IF(AND(ISNUMBER(F9),ISNUMBER(D9),F9=D9),1,0)+IF(AND(ISNUMBER(D10),ISNUMBER(F10),D10=F10),1,0) | O9: =IF(AND(ISNUMBER(F7),ISNUMBER(D7),F7<D7),1,0)+IF(AND(ISNUMBER(F9),ISNUMBER(D9),F9<D9),1,0)+IF(AND(ISNUMBER(D10),ISNUMBER(F10),D10<F10),1,0) | P9: =IF(ISNUMBER(F7),F7,0)+IF(ISNUMBER(F9),F9,0)+IF(ISNUMBER(D10),D10,0) | Q9: =IF(ISNUMBER(D7),D7,0)+IF(ISNUMBER(D9),D9,0)+IF(ISNUMBER(F10),F10,0) | R9: =P9-Q9 | S9: =M9*3+N9 | T9: =S9*100000000 + (R9+100)*100000 + P9*1000 + IFERROR(VLOOKUP(K9, RankingFIFA!$A$1:$B$48, 2, FALSE), 0)
C10: Chequia | D10: 1 | E10: - | F10: 3 | G10: México | H10: =IF(AND(ISNUMBER(D10),ISNUMBER(F10)),"Ok","")
C11: Sudáfrica | D11: 0 | E11: - | F11: 1 | G11: Corea del Sur | H11: =IF(AND(ISNUMBER(D11),ISNUMBER(F11)),"Ok","") | J11: CLASIFICACIÓN GRUPO B
J12: B | K12: Canadá | L12: =IF(ISNUMBER(D14),1,0)+IF(ISNUMBER(D16),1,0)+IF(ISNUMBER(F18),1,0) | M12: =IF(AND(ISNUMBER(D14),ISNUMBER(F14),D14>F14),1,0)+IF(AND(ISNUMBER(D16),ISNUMBER(F16),D16>F16),1,0)+IF(AND(ISNUMBER(F18),ISNUMBER(D18),F18>D18),1,0) | N12: =IF(AND(ISNUMBER(D14),ISNUMBER(F14),D14=F14),1,0)+IF(AND(ISNUMBER(D16),ISNUMBER(F16),D16=F16),1,0)+IF(AND(ISNUMBER(F18),ISNUMBER(D18),F18=D18),1,0) | O12: =IF(AND(ISNUMBER(D14),ISNUMBER(F14),D14<F14),1,0)+IF(AND(ISNUMBER(D16),ISNUMBER(F16),D16<F16),1,0)+IF(AND(ISNUMBER(F18),ISNUMBER(D18),F18<D18),1,0) | P12: =IF(ISNUMBER(D14),D14,0)+IF(ISNUMBER(D16),D16,0)+IF(ISNUMBER(F18),F18,0) | Q12: =IF(ISNUMBER(F14),F14,0)+IF(ISNUMBER(F16),F16,0)+IF(ISNUMBER(D18),D18,0) | R12: =P12-Q12 | S12: =M12*3+N12 | T12: =S12*100000000 + (R12+100)*100000 + P12*1000 + IFERROR(VLOOKUP(K12, RankingFIFA!$A$1:$B$48, 2, FALSE), 0)
A13: GRUPO B | J13: B | K13: Bosnia y Herze. | L13: =IF(ISNUMBER(F14),1,0)+IF(ISNUMBER(D17),1,0)+IF(ISNUMBER(D19),1,0) | M13: =IF(AND(ISNUMBER(F14),ISNUMBER(D14),F14>D14),1,0)+IF(AND(ISNUMBER(D17),ISNUMBER(F17),D17>F17),1,0)+IF(AND(ISNUMBER(D19),ISNUMBER(F19),D19>F19),1,0) | N13: =IF(AND(ISNUMBER(F14),ISNUMBER(D14),F14=D14),1,0)+IF(AND(ISNUMBER(D17),ISNUMBER(F17),D17=F17),1,0)+IF(AND(ISNUMBER(D19),ISNUMBER(F19),D19=F19),1,0) | O13: =IF(AND(ISNUMBER(F14),ISNUMBER(D14),F14<D14),1,0)+IF(AND(ISNUMBER(D17),ISNUMBER(F17),D17<F17),1,0)+IF(AND(ISNUMBER(D19),ISNUMBER(F19),D19<F19),1,0) | P13: =IF(ISNUMBER(F14),F14,0)+IF(ISNUMBER(D17),D17,0)+IF(ISNUMBER(D19),D19,0) | Q13: =IF(ISNUMBER(D14),D14,0)+IF(ISNUMBER(F17),F17,0)+IF(ISNUMBER(F19),F19,0) | R13: =P13-Q13 | S13: =M13*3+N13 | T13: =S13*100000000 + (R13+100)*100000 + P13*1000 + IFERROR(VLOOKUP(K13, RankingFIFA!$A$1:$B$48, 2, FALSE), 0)
C14: Canadá | D14: 2 | E14: - | F14: 2 | G14: Bosnia y Herze. | H14: =IF(AND(ISNUMBER(D14),ISNUMBER(F14)),"Ok","") | J14: B | K14: Qatar | L14: =IF(ISNUMBER(D15),1,0)+IF(ISNUMBER(F16),1,0)+IF(ISNUMBER(F19),1,0) | M14: =IF(AND(ISNUMBER(D15),ISNUMBER(F15),D15>F15),1,0)+IF(AND(ISNUMBER(F16),ISNUMBER(D16),F16>D16),1,0)+IF(AND(ISNUMBER(F19),ISNUMBER(D19),F19>D19),1,0) | N14: =IF(AND(ISNUMBER(D15),ISNUMBER(F15),D15=F15),1,0)+IF(AND(ISNUMBER(F16),ISNUMBER(D16),F16=D16),1,0)+IF(AND(ISNUMBER(F19),ISNUMBER(D19),F19=D19),1,0) | O14: =IF(AND(ISNUMBER(D15),ISNUMBER(F15),D15<F15),1,0)+IF(AND(ISNUMBER(F16),ISNUMBER(D16),F16<D16),1,0)+IF(AND(ISNUMBER(F19),ISNUMBER(D19),F19<D19),1,0) | P14: =IF(ISNUMBER(D15),D15,0)+IF(ISNUMBER(F16),F16,0)+IF(ISNUMBER(F19),F19,0) | Q14: =IF(ISNUMBER(F15),F15,0)+IF(ISNUMBER(D16),D16,0)+IF(ISNUMBER(D19),D19,0) | R14: =P14-Q14 | S14: =M14*3+N14 | T14: =S14*100000000 + (R14+100)*100000 + P14*1000 + IFERROR(VLOOKUP(K14, RankingFIFA!$A$1:$B$48, 2, FALSE), 0)
C15: Qatar | D15: 0 | E15: - | F15: 1 | G15: Suiza | H15: =IF(AND(ISNUMBER(D15),ISNUMBER(F15)),"Ok","") | J15: B | K15: Suiza | L15: =IF(ISNUMBER(F15),1,0)+IF(ISNUMBER(F17),1,0)+IF(ISNUMBER(D18),1,0) | M15: =IF(AND(ISNUMBER(F15),ISNUMBER(D15),F15>D15),1,0)+IF(AND(ISNUMBER(F17),ISNUMBER(D17),F17>D17),1,0)+IF(AND(ISNUMBER(D18),ISNUMBER(F18),D18>F18),1,0) | N15: =IF(AND(ISNUMBER(F15),ISNUMBER(D15),F15=D15),1,0)+IF(AND(ISNUMBER(F17),ISNUMBER(D17),F17=D17),1,0)+IF(AND(ISNUMBER(D18),ISNUMBER(F18),D18=F18),1,0) | O15: =IF(AND(ISNUMBER(F15),ISNUMBER(D15),F15<D15),1,0)+IF(AND(ISNUMBER(F17),ISNUMBER(D17),F17<D17),1,0)+IF(AND(ISNUMBER(D18),ISNUMBER(F18),D18<F18),1,0) | P15: =IF(ISNUMBER(F15),F15,0)+IF(ISNUMBER(F17),F17,0)+IF(ISNUMBER(D18),D18,0) | Q15: =IF(ISNUMBER(D15),D15,0)+IF(ISNUMBER(D17),D17,0)+IF(ISNUMBER(F18),F18,0) | R15: =P15-Q15 | S15: =M15*3+N15 | T15: =S15*100000000 + (R15+100)*100000 + P15*1000 + IFERROR(VLOOKUP(K15, RankingFIFA!$A$1:$B$48, 2, FALSE), 0)
C16: Canadá | D16: 3 | E16: - | F16: 1 | G16: Qatar | H16: =IF(AND(ISNUMBER(D16),ISNUMBER(F16)),"Ok","")
C17: Bosnia y Herze. | D17: 1 | E17: - | F17: 3 | G17: Suiza | H17: =IF(AND(ISNUMBER(D17),ISNUMBER(F17)),"Ok","") | J17: CLASIFICACIÓN GRUPO C
C18: Suiza | D18: 1 | E18: - | F18: 3 | G18: Canadá | H18: =IF(AND(ISNUMBER(D18),ISNUMBER(F18)),"Ok","") | J18: C | K18: Brasil | L18: =IF(ISNUMBER(D22),1,0)+IF(ISNUMBER(D24),1,0)+IF(ISNUMBER(F26),1,0) | M18: =IF(AND(ISNUMBER(D22),ISNUMBER(F22),D22>F22),1,0)+IF(AND(ISNUMBER(D24),ISNUMBER(F24),D24>F24),1,0)+IF(AND(ISNUMBER(F26),ISNUMBER(D26),F26>D26),1,0) | N18: =IF(AND(ISNUMBER(D22),ISNUMBER(F22),D22=F22),1,0)+IF(AND(ISNUMBER(D24),ISNUMBER(F24),D24=F24),1,0)+IF(AND(ISNUMBER(F26),ISNUMBER(D26),F26=D26),1,0) | O18: =IF(AND(ISNUMBER(D22),ISNUMBER(F22),D22<F22),1,0)+IF(AND(ISNUMBER(D24),ISNUMBER(F24),D24<F24),1,0)+IF(AND(ISNUMBER(F26),ISNUMBER(D26),F26<D26),1,0) | P18: =IF(ISNUMBER(D22),D22,0)+IF(ISNUMBER(D24),D24,0)+IF(ISNUMBER(F26),F26,0) | Q18: =IF(ISNUMBER(F22),F22,0)+IF(ISNUMBER(F24),F24,0)+IF(ISNUMBER(D26),D26,0) | R18: =P18-Q18 | S18: =M18*3+N18 | T18: =S18*100000000 + (R18+100)*100000 + P18*1000 + IFERROR(VLOOKUP(K18, RankingFIFA!$A$1:$B$48, 2, FALSE), 0)
C19: Bosnia y Herze. | D19: 0 | E19: - | F19: 0 | G19: Qatar | H19: =IF(AND(ISNUMBER(D19),ISNUMBER(F19)),"Ok","") | J19: C | K19: Marruecos | L19: =IF(ISNUMBER(F22),1,0)+IF(ISNUMBER(D25),1,0)+IF(ISNUMBER(D27),1,0) | M19: =IF(AND(ISNUMBER(F22),ISNUMBER(D22),F22>D22),1,0)+IF(AND(ISNUMBER(D25),ISNUMBER(F25),D25>F25),1,0)+IF(AND(ISNUMBER(D27),ISNUMBER(F27),D27>F27),1,0) | N19: =IF(AND(ISNUMBER(F22),ISNUMBER(D22),F22=D22),1,0)+IF(AND(ISNUMBER(D25),ISNUMBER(F25),D25=F25),1,0)+IF(AND(ISNUMBER(D27),ISNUMBER(F27),D27=F27),1,0) | O19: =IF(AND(ISNUMBER(F22),ISNUMBER(D22),F22<D22),1,0)+IF(AND(ISNUMBER(D25),ISNUMBER(F25),D25<F25),1,0)+IF(AND(ISNUMBER(D27),ISNUMBER(F27),D27<F27),1,0) | P19: =IF(ISNUMBER(F22),F22,0)+IF(ISNUMBER(D25),D25,0)+IF(ISNUMBER(D27),D27,0) | Q19: =IF(ISNUMBER(D22),D22,0)+IF(ISNUMBER(F25),F25,0)+IF(ISNUMBER(F27),F27,0) | R19: =P19-Q19 | S19: =M19*3+N19 | T19: =S19*100000000 + (R19+100)*100000 + P19*1000 + IFERROR(VLOOKUP(K19, RankingFIFA!$A$1:$B$48, 2, FALSE), 0)
J20: C | K20: Haití | L20: =IF(ISNUMBER(D23),1,0)+IF(ISNUMBER(F24),1,0)+IF(ISNUMBER(F27),1,0) | M20: =IF(AND(ISNUMBER(D23),ISNUMBER(F23),D23>F23),1,0)+IF(AND(ISNUMBER(F24),ISNUMBER(D24),F24>D24),1,0)+IF(AND(ISNUMBER(F27),ISNUMBER(D27),F27>D27),1,0) | N20: =IF(AND(ISNUMBER(D23),ISNUMBER(F23),D23=F23),1,0)+IF(AND(ISNUMBER(F24),ISNUMBER(D24),F24=D24),1,0)+IF(AND(ISNUMBER(F27),ISNUMBER(D27),F27=D27),1,0) | O20: =IF(AND(ISNUMBER(D23),ISNUMBER(F23),D23<F23),1,0)+IF(AND(ISNUMBER(F24),ISNUMBER(D24),F24<D24),1,0)+IF(AND(ISNUMBER(F27),ISNUMBER(D27),F27<D27),1,0) | P20: =IF(ISNUMBER(D23),D23,0)+IF(ISNUMBER(F24),F24,0)+IF(ISNUMBER(F27),F27,0) | Q20: =IF(ISNUMBER(F23),F23,0)+IF(ISNUMBER(D24),D24,0)+IF(ISNUMBER(D27),D27,0) | R20: =P20-Q20 | S20: =M20*3+N20 | T20: =S20*100000000 + (R20+100)*100000 + P20*1000 + IFERROR(VLOOKUP(K20, RankingFIFA!$A$1:$B$48, 2, FALSE), 0)
A21: GRUPO C | J21: C | K21: Escocia | L21: =IF(ISNUMBER(F23),1,0)+IF(ISNUMBER(F25),1,0)+IF(ISNUMBER(D26),1,0) | M21: =IF(AND(ISNUMBER(F23),ISNUMBER(D23),F23>D23),1,0)+IF(AND(ISNUMBER(F25),ISNUMBER(D25),F25>D25),1,0)+IF(AND(ISNUMBER(D26),ISNUMBER(F26),D26>F26),1,0) | N21: =IF(AND(ISNUMBER(F23),ISNUMBER(D23),F23=D23),1,0)+IF(AND(ISNUMBER(F25),ISNUMBER(D25),F25=D25),1,0)+IF(AND(ISNUMBER(D26),ISNUMBER(F26),D26=F26),1,0) | O21: =IF(AND(ISNUMBER(F23),ISNUMBER(D23),F23<D23),1,0)+IF(AND(ISNUMBER(F25),ISNUMBER(D25),F25<D25),1,0)+IF(AND(ISNUMBER(D26),ISNUMBER(F26),D26<F26),1,0) | P21: =IF(ISNUMBER(F23),F23,0)+IF(ISNUMBER(F25),F25,0)+IF(ISNUMBER(D26),D26,0) | Q21: =IF(ISNUMBER(D23),D23,0)+IF(ISNUMBER(D25),D25,0)+IF(ISNUMBER(F26),F26,0) | R21: =P21-Q21 | S21: =M21*3+N21 | T21: =S21*100000000 + (R21+100)*100000 + P21*1000 + IFERROR(VLOOKUP(K21, RankingFIFA!$A$1:$B$48, 2, FALSE), 0)
C22: Brasil | D22: 3 | E22: - | F22: 0 | G22: Marruecos | H22: =IF(AND(ISNUMBER(D22),ISNUMBER(F22)),"Ok","")
C23: Haití | D23: 0 | E23: - | F23: 2 | G23: Escocia | H23: =IF(AND(ISNUMBER(D23),ISNUMBER(F23)),"Ok","") | J23: CLASIFICACIÓN GRUPO D
C24: Brasil | D24: 4 | E24: - | F24: 1 | G24: Haití | H24: =IF(AND(ISNUMBER(D24),ISNUMBER(F24)),"Ok","") | J24: D | K24: Estados Unidos | L24: =IF(ISNUMBER(D30),1,0)+IF(ISNUMBER(D32),1,0)+IF(ISNUMBER(F34),1,0) | M24: =IF(AND(ISNUMBER(D30),ISNUMBER(F30),D30>F30),1,0)+IF(AND(ISNUMBER(D32),ISNUMBER(F32),D32>F32),1,0)+IF(AND(ISNUMBER(F34),ISNUMBER(D34),F34>D34),1,0) | N24: =IF(AND(ISNUMBER(D30),ISNUMBER(F30),D30=F30),1,0)+IF(AND(ISNUMBER(D32),ISNUMBER(F32),D32=F32),1,0)+IF(AND(ISNUMBER(F34),ISNUMBER(D34),F34=D34),1,0) | O24: =IF(AND(ISNUMBER(D30),ISNUMBER(F30),D30<F30),1,0)+IF(AND(ISNUMBER(D32),ISNUMBER(F32),D32<F32),1,0)+IF(AND(ISNUMBER(F34),ISNUMBER(D34),F34<D34),1,0) | P24: =IF(ISNUMBER(D30),D30,0)+IF(ISNUMBER(D32),D32,0)+IF(ISNUMBER(F34),F34,0) | Q24: =IF(ISNUMBER(F30),F30,0)+IF(ISNUMBER(F32),F32,0)+IF(ISNUMBER(D34),D34,0) | R24: =P24-Q24 | S24: =M24*3+N24 | T24: =S24*100000000 + (R24+100)*100000 + P24*1000 + IFERROR(VLOOKUP(K24, RankingFIFA!$A$1:$B$48, 2, FALSE), 0)
C25: Marruecos | D25: 3 | E25: - | F25: 1 | G25: Escocia | H25: =IF(AND(ISNUMBER(D25),ISNUMBER(F25)),"Ok","") | J25: D | K25: Paraguay | L25: =IF(ISNUMBER(F30),1,0)+IF(ISNUMBER(D33),1,0)+IF(ISNUMBER(D35),1,0) | M25: =IF(AND(ISNUMBER(F30),ISNUMBER(D30),F30>D30),1,0)+IF(AND(ISNUMBER(D33),ISNUMBER(F33),D33>F33),1,0)+IF(AND(ISNUMBER(D35),ISNUMBER(F35),D35>F35),1,0) | N25: =IF(AND(ISNUMBER(F30),ISNUMBER(D30),F30=D30),1,0)+IF(AND(ISNUMBER(D33),ISNUMBER(F33),D33=F33),1,0)+IF(AND(ISNUMBER(D35),ISNUMBER(F35),D35=F35),1,0) | O25: =IF(AND(ISNUMBER(F30),ISNUMBER(D30),F30<D30),1,0)+IF(AND(ISNUMBER(D33),ISNUMBER(F33),D33<F33),1,0)+IF(AND(ISNUMBER(D35),ISNUMBER(F35),D35<F35),1,0) | P25: =IF(ISNUMBER(F30),F30,0)+IF(ISNUMBER(D33),D33,0)+IF(ISNUMBER(D35),D35,0) | Q25: =IF(ISNUMBER(D30),D30,0)+IF(ISNUMBER(F33),F33,0)+IF(ISNUMBER(F35),F35,0) | R25: =P25-Q25 | S25: =M25*3+N25 | T25: =S25*100000000 + (R25+100)*100000 + P25*1000 + IFERROR(VLOOKUP(K25, RankingFIFA!$A$1:$B$48, 2, FALSE), 0)
C26: Escocia | D26: 1 | E26: - | F26: 5 | G26: Brasil | H26: =IF(AND(ISNUMBER(D26),ISNUMBER(F26)),"Ok","") | J26: D | K26: Australia | L26: =IF(ISNUMBER(D31),1,0)+IF(ISNUMBER(F32),1,0)+IF(ISNUMBER(F35),1,0) | M26: =IF(AND(ISNUMBER(D31),ISNUMBER(F31),D31>F31),1,0)+IF(AND(ISNUMBER(F32),ISNUMBER(D32),F32>D32),1,0)+IF(AND(ISNUMBER(F35),ISNUMBER(D35),F35>D35),1,0) | N26: =IF(AND(ISNUMBER(D31),ISNUMBER(F31),D31=F31),1,0)+IF(AND(ISNUMBER(F32),ISNUMBER(D32),F32=D32),1,0)+IF(AND(ISNUMBER(F35),ISNUMBER(D35),F35=D35),1,0) | O26: =IF(AND(ISNUMBER(D31),ISNUMBER(F31),D31<F31),1,0)+IF(AND(ISNUMBER(F32),ISNUMBER(D32),F32<D32),1,0)+IF(AND(ISNUMBER(F35),ISNUMBER(D35),F35<D35),1,0) | P26: =IF(ISNUMBER(D31),D31,0)+IF(ISNUMBER(F32),F32,0)+IF(ISNUMBER(F35),F35,0) | Q26: =IF(ISNUMBER(F31),F31,0)+IF(ISNUMBER(D32),D32,0)+IF(ISNUMBER(D35),D35,0) | R26: =P26-Q26 | S26: =M26*3+N26 | T26: =S26*100000000 + (R26+100)*100000 + P26*1000 + IFERROR(VLOOKUP(K26, RankingFIFA!$A$1:$B$48, 2, FALSE), 0)
C27: Marruecos | D27: 2 | E27: - | F27: 1 | G27: Haití | H27: =IF(AND(ISNUMBER(D27),ISNUMBER(F27)),"Ok","") | J27: D | K27: Turquía | L27: =IF(ISNUMBER(F31),1,0)+IF(ISNUMBER(F33),1,0)+IF(ISNUMBER(D34),1,0) | M27: =IF(AND(ISNUMBER(F31),ISNUMBER(D31),F31>D31),1,0)+IF(AND(ISNUMBER(F33),ISNUMBER(D33),F33>D33),1,0)+IF(AND(ISNUMBER(D34),ISNUMBER(F34),D34>F34),1,0) | N27: =IF(AND(ISNUMBER(F31),ISNUMBER(D31),F31=D31),1,0)+IF(AND(ISNUMBER(F33),ISNUMBER(D33),F33=D33),1,0)+IF(AND(ISNUMBER(D34),ISNUMBER(F34),D34=F34),1,0) | O27: =IF(AND(ISNUMBER(F31),ISNUMBER(D31),F31<D31),1,0)+IF(AND(ISNUMBER(F33),ISNUMBER(D33),F33<D33),1,0)+IF(AND(ISNUMBER(D34),ISNUMBER(F34),D34<F34),1,0) | P27: =IF(ISNUMBER(F31),F31,0)+IF(ISNUMBER(F33),F33,0)+IF(ISNUMBER(D34),D34,0) | Q27: =IF(ISNUMBER(D31),D31,0)+IF(ISNUMBER(D33),D33,0)+IF(ISNUMBER(F34),F34,0) | R27: =P27-Q27 | S27: =M27*3+N27 | T27: =S27*100000000 + (R27+100)*100000 + P27*1000 + IFERROR(VLOOKUP(K27, RankingFIFA!$A$1:$B$48, 2, FALSE), 0)
A29: GRUPO D | J29: CLASIFICACIÓN GRUPO E
C30: Estados Unidos | D30: 2 | E30: - | F30: 2 | G30: Paraguay | H30: =IF(AND(ISNUMBER(D30),ISNUMBER(F30)),"Ok","") | J30: E | K30: Alemania | L30: =IF(ISNUMBER(D38),1,0)+IF(ISNUMBER(D40),1,0)+IF(ISNUMBER(F42),1,0) | M30: =IF(AND(ISNUMBER(D38),ISNUMBER(F38),D38>F38),1,0)+IF(AND(ISNUMBER(D40),ISNUMBER(F40),D40>F40),1,0)+IF(AND(ISNUMBER(F42),ISNUMBER(D42),F42>D42),1,0) | N30: =IF(AND(ISNUMBER(D38),ISNUMBER(F38),D38=F38),1,0)+IF(AND(ISNUMBER(D40),ISNUMBER(F40),D40=F40),1,0)+IF(AND(ISNUMBER(F42),ISNUMBER(D42),F42=D42),1,0) | O30: =IF(AND(ISNUMBER(D38),ISNUMBER(F38),D38<F38),1,0)+IF(AND(ISNUMBER(D40),ISNUMBER(F40),D40<F40),1,0)+IF(AND(ISNUMBER(F42),ISNUMBER(D42),F42<D42),1,0) | P30: =IF(ISNUMBER(D38),D38,0)+IF(ISNUMBER(D40),D40,0)+IF(ISNUMBER(F42),F42,0) | Q30: =IF(ISNUMBER(F38),F38,0)+IF(ISNUMBER(F40),F40,0)+IF(ISNUMBER(D42),D42,0) | R30: =P30-Q30 | S30: =M30*3+N30 | T30: =S30*100000000 + (R30+100)*100000 + P30*1000 + IFERROR(VLOOKUP(K30, RankingFIFA!$A$1:$B$48, 2, FALSE), 0)
C31: Australia | D31: 1 | E31: - | F31: 3 | G31: Turquía | H31: =IF(AND(ISNUMBER(D31),ISNUMBER(F31)),"Ok","") | J31: E | K31: Curaçao | L31: =IF(ISNUMBER(F38),1,0)+IF(ISNUMBER(D41),1,0)+IF(ISNUMBER(D43),1,0) | M31: =IF(AND(ISNUMBER(F38),ISNUMBER(D38),F38>D38),1,0)+IF(AND(ISNUMBER(D41),ISNUMBER(F41),D41>F41),1,0)+IF(AND(ISNUMBER(D43),ISNUMBER(F43),D43>F43),1,0) | N31: =IF(AND(ISNUMBER(F38),ISNUMBER(D38),F38=D38),1,0)+IF(AND(ISNUMBER(D41),ISNUMBER(F41),D41=F41),1,0)+IF(AND(ISNUMBER(D43),ISNUMBER(F43),D43=F43),1,0) | O31: =IF(AND(ISNUMBER(F38),ISNUMBER(D38),F38<D38),1,0)+IF(AND(ISNUMBER(D41),ISNUMBER(F41),D41<F41),1,0)+IF(AND(ISNUMBER(D43),ISNUMBER(F43),D43<F43),1,0) | P31: =IF(ISNUMBER(F38),F38,0)+IF(ISNUMBER(D41),D41,0)+IF(ISNUMBER(D43),D43,0) | Q31: =IF(ISNUMBER(D38),D38,0)+IF(ISNUMBER(F41),F41,0)+IF(ISNUMBER(F43),F43,0) | R31: =P31-Q31 | S31: =M31*3+N31 | T31: =S31*100000000 + (R31+100)*100000 + P31*1000 + IFERROR(VLOOKUP(K31, RankingFIFA!$A$1:$B$48, 2, FALSE), 0)
C32: Estados Unidos | D32: 1 | E32: - | F32: 1 | G32: Australia | H32: =IF(AND(ISNUMBER(D32),ISNUMBER(F32)),"Ok","") | J32: E | K32: Costa de Marfil | L32: =IF(ISNUMBER(D39),1,0)+IF(ISNUMBER(F40),1,0)+IF(ISNUMBER(F43),1,0) | M32: =IF(AND(ISNUMBER(D39),ISNUMBER(F39),D39>F39),1,0)+IF(AND(ISNUMBER(F40),ISNUMBER(D40),F40>D40),1,0)+IF(AND(ISNUMBER(F43),ISNUMBER(D43),F43>D43),1,0) | N32: =IF(AND(ISNUMBER(D39),ISNUMBER(F39),D39=F39),1,0)+IF(AND(ISNUMBER(F40),ISNUMBER(D40),F40=D40),1,0)+IF(AND(ISNUMBER(F43),ISNUMBER(D43),F43=D43),1,0) | O32: =IF(AND(ISNUMBER(D39),ISNUMBER(F39),D39<F39),1,0)+IF(AND(ISNUMBER(F40),ISNUMBER(D40),F40<D40),1,0)+IF(AND(ISNUMBER(F43),ISNUMBER(D43),F43<D43),1,0) | P32: =IF(ISNUMBER(D39),D39,0)+IF(ISNUMBER(F40),F40,0)+IF(ISNUMBER(F43),F43,0) | Q32: =IF(ISNUMBER(F39),F39,0)+IF(ISNUMBER(D40),D40,0)+IF(ISNUMBER(D43),D43,0) | R32: =P32-Q32 | S32: =M32*3+N32 | T32: =S32*100000000 + (R32+100)*100000 + P32*1000 + IFERROR(VLOOKUP(K32, RankingFIFA!$A$1:$B$48, 2, FALSE), 0)
C33: Paraguay | D33: 0 | E33: - | F33: 0 | G33: Turquía | H33: =IF(AND(ISNUMBER(D33),ISNUMBER(F33)),"Ok","") | J33: E | K33: Ecuador | L33: =IF(ISNUMBER(F39),1,0)+IF(ISNUMBER(F41),1,0)+IF(ISNUMBER(D42),1,0) | M33: =IF(AND(ISNUMBER(F39),ISNUMBER(D39),F39>D39),1,0)+IF(AND(ISNUMBER(F41),ISNUMBER(D41),F41>D41),1,0)+IF(AND(ISNUMBER(D42),ISNUMBER(F42),D42>F42),1,0) | N33: =IF(AND(ISNUMBER(F39),ISNUMBER(D39),F39=D39),1,0)+IF(AND(ISNUMBER(F41),ISNUMBER(D41),F41=D41),1,0)+IF(AND(ISNUMBER(D42),ISNUMBER(F42),D42=F42),1,0) | O33: =IF(AND(ISNUMBER(F39),ISNUMBER(D39),F39<D39),1,0)+IF(AND(ISNUMBER(F41),ISNUMBER(D41),F41<D41),1,0)+IF(AND(ISNUMBER(D42),ISNUMBER(F42),D42<F42),1,0) | P33: =IF(ISNUMBER(F39),F39,0)+IF(ISNUMBER(F41),F41,0)+IF(ISNUMBER(D42),D42,0) | Q33: =IF(ISNUMBER(D39),D39,0)+IF(ISNUMBER(D41),D41,0)+IF(ISNUMBER(F42),F42,0) | R33: =P33-Q33 | S33: =M33*3+N33 | T33: =S33*100000000 + (R33+100)*100000 + P33*1000 + IFERROR(VLOOKUP(K33, RankingFIFA!$A$1:$B$48, 2, FALSE), 0)
C34: Turquía | D34: 3 | E34: - | F34: 2 | G34: Estados Unidos | H34: =IF(AND(ISNUMBER(D34),ISNUMBER(F34)),"Ok","")
C35: Paraguay | D35: 2 | E35: - | F35: 2 | G35: Australia | H35: =IF(AND(ISNUMBER(D35),ISNUMBER(F35)),"Ok","") | J35: CLASIFICACIÓN GRUPO F
J36: F | K36: Países Bajos | L36: =IF(ISNUMBER(D46),1,0)+IF(ISNUMBER(D48),1,0)+IF(ISNUMBER(F50),1,0) | M36: =IF(AND(ISNUMBER(D46),ISNUMBER(F46),D46>F46),1,0)+IF(AND(ISNUMBER(D48),ISNUMBER(F48),D48>F48),1,0)+IF(AND(ISNUMBER(F50),ISNUMBER(D50),F50>D50),1,0) | N36: =IF(AND(ISNUMBER(D46),ISNUMBER(F46),D46=F46),1,0)+IF(AND(ISNUMBER(D48),ISNUMBER(F48),D48=F48),1,0)+IF(AND(ISNUMBER(F50),ISNUMBER(D50),F50=D50),1,0) | O36: =IF(AND(ISNUMBER(D46),ISNUMBER(F46),D46<F46),1,0)+IF(AND(ISNUMBER(D48),ISNUMBER(F48),D48<F48),1,0)+IF(AND(ISNUMBER(F50),ISNUMBER(D50),F50<D50),1,0) | P36: =IF(ISNUMBER(D46),D46,0)+IF(ISNUMBER(D48),D48,0)+IF(ISNUMBER(F50),F50,0) | Q36: =IF(ISNUMBER(F46),F46,0)+IF(ISNUMBER(F48),F48,0)+IF(ISNUMBER(D50),D50,0) | R36: =P36-Q36 | S36: =M36*3+N36 | T36: =S36*100000000 + (R36+100)*100000 + P36*1000 + IFERROR(VLOOKUP(K36, RankingFIFA!$A$1:$B$48, 2, FALSE), 0)
A37: GRUPO E | J37: F | K37: Japón | L37: =IF(ISNUMBER(F46),1,0)+IF(ISNUMBER(D49),1,0)+IF(ISNUMBER(D51),1,0) | M37: =IF(AND(ISNUMBER(F46),ISNUMBER(D46),F46>D46),1,0)+IF(AND(ISNUMBER(D49),ISNUMBER(F49),D49>F49),1,0)+IF(AND(ISNUMBER(D51),ISNUMBER(F51),D51>F51),1,0) | N37: =IF(AND(ISNUMBER(F46),ISNUMBER(D46),F46=D46),1,0)+IF(AND(ISNUMBER(D49),ISNUMBER(F49),D49=F49),1,0)+IF(AND(ISNUMBER(D51),ISNUMBER(F51),D51=F51),1,0) | O37: =IF(AND(ISNUMBER(F46),ISNUMBER(D46),F46<D46),1,0)+IF(AND(ISNUMBER(D49),ISNUMBER(F49),D49<F49),1,0)+IF(AND(ISNUMBER(D51),ISNUMBER(F51),D51<F51),1,0) | P37: =IF(ISNUMBER(F46),F46,0)+IF(ISNUMBER(D49),D49,0)+IF(ISNUMBER(D51),D51,0) | Q37: =IF(ISNUMBER(D46),D46,0)+IF(ISNUMBER(F49),F49,0)+IF(ISNUMBER(F51),F51,0) | R37: =P37-Q37 | S37: =M37*3+N37 | T37: =S37*100000000 + (R37+100)*100000 + P37*1000 + IFERROR(VLOOKUP(K37, RankingFIFA!$A$1:$B$48, 2, FALSE), 0)
C38: Alemania | D38: 4 | E38: - | F38: 0 | G38: Curaçao | H38: =IF(AND(ISNUMBER(D38),ISNUMBER(F38)),"Ok","") | J38: F | K38: Suecia | L38: =IF(ISNUMBER(D47),1,0)+IF(ISNUMBER(F48),1,0)+IF(ISNUMBER(F51),1,0) | M38: =IF(AND(ISNUMBER(D47),ISNUMBER(F47),D47>F47),1,0)+IF(AND(ISNUMBER(F48),ISNUMBER(D48),F48>D48),1,0)+IF(AND(ISNUMBER(F51),ISNUMBER(D51),F51>D51),1,0) | N38: =IF(AND(ISNUMBER(D47),ISNUMBER(F47),D47=F47),1,0)+IF(AND(ISNUMBER(F48),ISNUMBER(D48),F48=D48),1,0)+IF(AND(ISNUMBER(F51),ISNUMBER(D51),F51=D51),1,0) | O38: =IF(AND(ISNUMBER(D47),ISNUMBER(F47),D47<F47),1,0)+IF(AND(ISNUMBER(F48),ISNUMBER(D48),F48<D48),1,0)+IF(AND(ISNUMBER(F51),ISNUMBER(D51),F51<D51),1,0) | P38: =IF(ISNUMBER(D47),D47,0)+IF(ISNUMBER(F48),F48,0)+IF(ISNUMBER(F51),F51,0) | Q38: =IF(ISNUMBER(F47),F47,0)+IF(ISNUMBER(D48),D48,0)+IF(ISNUMBER(D51),D51,0) | R38: =P38-Q38 | S38: =M38*3+N38 | T38: =S38*100000000 + (R38+100)*100000 + P38*1000 + IFERROR(VLOOKUP(K38, RankingFIFA!$A$1:$B$48, 2, FALSE), 0)
C39: Costa de Marfil | D39: 2 | E39: - | F39: 1 | G39: Ecuador | H39: =IF(AND(ISNUMBER(D39),ISNUMBER(F39)),"Ok","") | J39: F | K39: Túnez | L39: =IF(ISNUMBER(F47),1,0)+IF(ISNUMBER(F49),1,0)+IF(ISNUMBER(D50),1,0) | M39: =IF(AND(ISNUMBER(F47),ISNUMBER(D47),F47>D47),1,0)+IF(AND(ISNUMBER(F49),ISNUMBER(D49),F49>D49),1,0)+IF(AND(ISNUMBER(D50),ISNUMBER(F50),D50>F50),1,0) | N39: =IF(AND(ISNUMBER(F47),ISNUMBER(D47),F47=D47),1,0)+IF(AND(ISNUMBER(F49),ISNUMBER(D49),F49=D49),1,0)+IF(AND(ISNUMBER(D50),ISNUMBER(F50),D50=F50),1,0) | O39: =IF(AND(ISNUMBER(F47),ISNUMBER(D47),F47<D47),1,0)+IF(AND(ISNUMBER(F49),ISNUMBER(D49),F49<D49),1,0)+IF(AND(ISNUMBER(D50),ISNUMBER(F50),D50<F50),1,0) | P39: =IF(ISNUMBER(F47),F47,0)+IF(ISNUMBER(F49),F49,0)+IF(ISNUMBER(D50),D50,0) | Q39: =IF(ISNUMBER(D47),D47,0)+IF(ISNUMBER(D49),D49,0)+IF(ISNUMBER(F50),F50,0) | R39: =P39-Q39 | S39: =M39*3+N39 | T39: =S39*100000000 + (R39+100)*100000 + P39*1000 + IFERROR(VLOOKUP(K39, RankingFIFA!$A$1:$B$48, 2, FALSE), 0)
C40: Alemania | D40: 3 | E40: - | F40: 1 | G40: Costa de Marfil | H40: =IF(AND(ISNUMBER(D40),ISNUMBER(F40)),"Ok","")
C41: Curaçao | D41: 1 | E41: - | F41: 2 | G41: Ecuador | H41: =IF(AND(ISNUMBER(D41),ISNUMBER(F41)),"Ok","") | J41: CLASIFICACIÓN GRUPO G
C42: Ecuador | D42: 1 | E42: - | F42: 3 | G42: Alemania | H42: =IF(AND(ISNUMBER(D42),ISNUMBER(F42)),"Ok","") | J42: G | K42: Bélgica | L42: =IF(ISNUMBER(D54),1,0)+IF(ISNUMBER(D56),1,0)+IF(ISNUMBER(F58),1,0) | M42: =IF(AND(ISNUMBER(D54),ISNUMBER(F54),D54>F54),1,0)+IF(AND(ISNUMBER(D56),ISNUMBER(F56),D56>F56),1,0)+IF(AND(ISNUMBER(F58),ISNUMBER(D58),F58>D58),1,0) | N42: =IF(AND(ISNUMBER(D54),ISNUMBER(F54),D54=F54),1,0)+IF(AND(ISNUMBER(D56),ISNUMBER(F56),D56=F56),1,0)+IF(AND(ISNUMBER(F58),ISNUMBER(D58),F58=D58),1,0) | O42: =IF(AND(ISNUMBER(D54),ISNUMBER(F54),D54<F54),1,0)+IF(AND(ISNUMBER(D56),ISNUMBER(F56),D56<F56),1,0)+IF(AND(ISNUMBER(F58),ISNUMBER(D58),F58<D58),1,0) | P42: =IF(ISNUMBER(D54),D54,0)+IF(ISNUMBER(D56),D56,0)+IF(ISNUMBER(F58),F58,0) | Q42: =IF(ISNUMBER(F54),F54,0)+IF(ISNUMBER(F56),F56,0)+IF(ISNUMBER(D58),D58,0) | R42: =P42-Q42 | S42: =M42*3+N42 | T42: =S42*100000000 + (R42+100)*100000 + P42*1000 + IFERROR(VLOOKUP(K42, RankingFIFA!$A$1:$B$48, 2, FALSE), 0)
C43: Curaçao | D43: 1 | E43: - | F43: 2 | G43: Costa de Marfil | H43: =IF(AND(ISNUMBER(D43),ISNUMBER(F43)),"Ok","") | J43: G | K43: Egipto | L43: =IF(ISNUMBER(F54),1,0)+IF(ISNUMBER(D57),1,0)+IF(ISNUMBER(D59),1,0) | M43: =IF(AND(ISNUMBER(F54),ISNUMBER(D54),F54>D54),1,0)+IF(AND(ISNUMBER(D57),ISNUMBER(F57),D57>F57),1,0)+IF(AND(ISNUMBER(D59),ISNUMBER(F59),D59>F59),1,0) | N43: =IF(AND(ISNUMBER(F54),ISNUMBER(D54),F54=D54),1,0)+IF(AND(ISNUMBER(D57),ISNUMBER(F57),D57=F57),1,0)+IF(AND(ISNUMBER(D59),ISNUMBER(F59),D59=F59),1,0) | O43: =IF(AND(ISNUMBER(F54),ISNUMBER(D54),F54<D54),1,0)+IF(AND(ISNUMBER(D57),ISNUMBER(F57),D57<F57),1,0)+IF(AND(ISNUMBER(D59),ISNUMBER(F59),D59<F59),1,0) | P43: =IF(ISNUMBER(F54),F54,0)+IF(ISNUMBER(D57),D57,0)+IF(ISNUMBER(D59),D59,0) | Q43: =IF(ISNUMBER(D54),D54,0)+IF(ISNUMBER(F57),F57,0)+IF(ISNUMBER(F59),F59,0) | R43: =P43-Q43 | S43: =M43*3+N43 | T43: =S43*100000000 + (R43+100)*100000 + P43*1000 + IFERROR(VLOOKUP(K43, RankingFIFA!$A$1:$B$48, 2, FALSE), 0)
...

Sheet Mejores Terceros
B2: RANKING DE MEJORES TERCEROS LUGARES
B5: Posición | C5: Grupo | D5: Equipo | E5: PTS | F5: DIF | G5: Clasifica a 16avos
B6: 1 | C6: =Backend!B16 | D6: =Backend!C16 | E6: =IF(D6="","",VLOOKUP(D6, Grupos!$K$6:$S$77, 9, FALSE)) | F6: =IF(D6="","",VLOOKUP(D6, Grupos!$K$6:$R$77, 8, FALSE)) | G6: =IF(Backend!C16="","",IF(1<=8, "✅ Avanza", "❌ Eliminado"))
B7: 2 | C7: =Backend!B17 | D7: =Backend!C17 | E7: =IF(D7="","",VLOOKUP(D7, Grupos!$K$6:$S$77, 9, FALSE)) | F7: =IF(D7="","",VLOOKUP(D7, Grupos!$K$6:$R$77, 8, FALSE)) | G7: =IF(Backend!C17="","",IF(2<=8, "✅ Avanza", "❌ Eliminado"))
B8: 3 | C8: =Backend!B18 | D8: =Backend!C18 | E8: =IF(D8="","",VLOOKUP(D8, Grupos!$K$6:$S$77, 9, FALSE)) | F8: =IF(D8="","",VLOOKUP(D8, Grupos!$K$6:$R$77, 8, FALSE)) | G8: =IF(Backend!C18="","",IF(3<=8, "✅ Avanza", "❌ Eliminado"))
B9: 4 | C9: =Backend!B19 | D9: =Backend!C19 | E9: =IF(D9="","",VLOOKUP(D9, Grupos!$K$6:$S$77, 9, FALSE)) | F9: =IF(D9="","",VLOOKUP(D9, Grupos!$K$6:$R$77, 8, FALSE)) | G9: =IF(Backend!C19="","",IF(4<=8, "✅ Avanza", "❌ Eliminado"))
B10: 5 | C10: =Backend!B20 | D10: =Backend!C20 | E10: =IF(D10="","",VLOOKUP(D10, Grupos!$K$6:$S$77, 9, FALSE)) | F10: =IF(D10="","",VLOOKUP(D10, Grupos!$K$6:$R$77, 8, FALSE)) | G10: =IF(Backend!C20="","",IF(5<=8, "✅ Avanza", "❌ Eliminado"))
B11: 6 | C11: =Backend!B21 | D11: =Backend!C21 | E11: =IF(D11="","",VLOOKUP(D11, Grupos!$K$6:$S$77, 9, FALSE)) | F11: =IF(D11="","",VLOOKUP(D11, Grupos!$K$6:$R$77, 8, FALSE)) | G11: =IF(Backend!C21="","",IF(6<=8, "✅ Avanza", "❌ Eliminado"))
B12: 7 | C12: =Backend!B22 | D12: =Backend!C22 | E12: =IF(D12="","",VLOOKUP(D12, Grupos!$K$6:$S$77, 9, FALSE)) | F12: =IF(D12="","",VLOOKUP(D12, Grupos!$K$6:$R$77, 8, FALSE)) | G12: =IF(Backend!C22="","",IF(7<=8, "✅ Avanza", "❌ Eliminado"))
B13: 8 | C13: =Backend!B23 | D13: =Backend!C23 | E13: =IF(D13="","",VLOOKUP(D13, Grupos!$K$6:$S$77, 9, FALSE)) | F13: =IF(D13="","",VLOOKUP(D13, Grupos!$K$6:$R$77, 8, FALSE)) | G13: =IF(Backend!C23="","",IF(8<=8, "✅ Avanza", "❌ Eliminado"))
B14: 9 | C14: =Backend!B24 | D14: =Backend!C24 | E14: =IF(D14="","",VLOOKUP(D14, Grupos!$K$6:$S$77, 9, FALSE)) | F14: =IF(D14="","",VLOOKUP(D14, Grupos!$K$6:$R$77, 8, FALSE)) | G14: =IF(Backend!C24="","",IF(9<=8, "✅ Avanza", "❌ Eliminado"))
B15: 10 | C15: =Backend!B25 | D15: =Backend!C25 | E15: =IF(D15="","",VLOOKUP(D15, Grupos!$K$6:$S$77, 9, FALSE)) | F15: =IF(D15="","",VLOOKUP(D15, Grupos!$K$6:$R$77, 8, FALSE)) | G15: =IF(Backend!C25="","",IF(10<=8, "✅ Avanza", "❌ Eliminado"))
B16: 11 | C16: =Backend!B26 | D16: =Backend!C26 | E16: =IF(D16="","",VLOOKUP(D16, Grupos!$K$6:$S$77, 9, FALSE)) | F16: =IF(D16="","",VLOOKUP(D16, Grupos!$K$6:$R$77, 8, FALSE)) | G16: =IF(Backend!C26="","",IF(11<=8, "✅ Avanza", "❌ Eliminado"))
B17: 12 | C17: =Backend!B27 | D17: =Backend!C27 | E17: =IF(D17="","",VLOOKUP(D17, Grupos!$K$6:$S$77, 9, FALSE)) | F17: =IF(D17="","",VLOOKUP(D17, Grupos!$K$6:$R$77, 8, FALSE)) | G17: =IF(Backend!C27="","",IF(12<=8, "✅ Avanza", "❌ Eliminado"))

Sheet Backend
A1: Grupo | B1: 1ro | C1: 2do | D1: 3ro | E1: 3ro Index
A2: A | B2: =INDEX(Grupos!$K$6:$K$9, MATCH(LARGE(Grupos!$T$6:$T$9, 1), Grupos!$T$6:$T$9, 0)) | C2: =INDEX(Grupos!$K$6:$K$9, MATCH(LARGE(Grupos!$T$6:$T$9, 2), Grupos!$T$6:$T$9, 0)) | D2: =INDEX(Grupos!$K$6:$K$9, MATCH(LARGE(Grupos!$T$6:$T$9, 3), Grupos!$T$6:$T$9, 0)) | E2: =LARGE(Grupos!$T$6:$T$9, 3)
A3: B | B3: =INDEX(Grupos!$K$12:$K$15, MATCH(LARGE(Grupos!$T$12:$T$15, 1), Grupos!$T$12:$T$15, 0)) | C3: =INDEX(Grupos!$K$12:$K$15, MATCH(LARGE(Grupos!$T$12:$T$15, 2), Grupos!$T$12:$T$15, 0)) | D3: =INDEX(Grupos!$K$12:$K$15, MATCH(LARGE(Grupos!$T$12:$T$15, 3), Grupos!$T$12:$T$15, 0)) | E3: =LARGE(Grupos!$T$12:$T$15, 3)
A4: C | B4: =INDEX(Grupos!$K$18:$K$21, MATCH(LARGE(Grupos!$T$18:$T$21, 1), Grupos!$T$18:$T$21, 0)) | C4: =INDEX(Grupos!$K$18:$K$21, MATCH(LARGE(Grupos!$T$18:$T$21, 2), Grupos!$T$18:$T$21, 0)) | D4: =INDEX(Grupos!$K$18:$K$21, MATCH(LARGE(Grupos!$T$18:$T$21, 3), Grupos!$T$18:$T$21, 0)) | E4: =LARGE(Grupos!$T$18:$T$21, 3)
A5: D | B5: =INDEX(Grupos!$K$24:$K$27, MATCH(LARGE(Grupos!$T$24:$T$27, 1), Grupos!$T$24:$T$27, 0)) | C5: =INDEX(Grupos!$K$24:$K$27, MATCH(LARGE(Grupos!$T$24:$T$27, 2), Grupos!$T$24:$T$27, 0)) | D5: =INDEX(Grupos!$K$24:$K$27, MATCH(LARGE(Grupos!$T$24:$T$27, 3), Grupos!$T$24:$T$27, 0)) | E5: =LARGE(Grupos!$T$24:$T$27, 3)
A6: E | B6: =INDEX(Grupos!$K$30:$K$33, MATCH(LARGE(Grupos!$T$30:$T$33, 1), Grupos!$T$30:$T$33, 0)) | C6: =INDEX(Grupos!$K$30:$K$33, MATCH(LARGE(Grupos!$T$30:$T$33, 2), Grupos!$T$30:$T$33, 0)) | D6: =INDEX(Grupos!$K$30:$K$33, MATCH(LARGE(Grupos!$T$30:$T$33, 3), Grupos!$T$30:$T$33, 0)) | E6: =LARGE(Grupos!$T$30:$T$33, 3)
A7: F | B7: =INDEX(Grupos!$K$36:$K$39, MATCH(LARGE(Grupos!$T$36:$T$39, 1), Grupos!$T$36:$T$39, 0)) | C7: =INDEX(Grupos!$K$36:$K$39, MATCH(LARGE(Grupos!$T$36:$T$39, 2), Grupos!$T$36:$T$39, 0)) | D7: =INDEX(Grupos!$K$36:$K$39, MATCH(LARGE(Grupos!$T$36:$T$39, 3), Grupos!$T$36:$T$39, 0)) | E7: =LARGE(Grupos!$T$36:$T$39, 3)
A8: G | B8: =INDEX(Grupos!$K$42:$K$45, MATCH(LARGE(Grupos!$T$42:$T$45, 1), Grupos!$T$42:$T$45, 0)) | C8: =INDEX(Grupos!$K$42:$K$45, MATCH(LARGE(Grupos!$T$42:$T$45, 2), Grupos!$T$42:$T$45, 0)) | D8: =INDEX(Grupos!$K$42:$K$45, MATCH(LARGE(Grupos!$T$42:$T$45, 3), Grupos!$T$42:$T$45, 0)) | E8: =LARGE(Grupos!$T$42:$T$45, 3)
A9: H | B9: =INDEX(Grupos!$K$48:$K$51, MATCH(LARGE(Grupos!$T$48:$T$51, 1), Grupos!$T$48:$T$51, 0)) | C9: =INDEX(Grupos!$K$48:$K$51, MATCH(LARGE(Grupos!$T$48:$T$51, 2), Grupos!$T$48:$T$51, 0)) | D9: =INDEX(Grupos!$K$48:$K$51, MATCH(LARGE(Grupos!$T$48:$T$51, 3), Grupos!$T$48:$T$51, 0)) | E9: =LARGE(Grupos!$T$48:$T$51, 3)
A10: I | B10: =INDEX(Grupos!$K$54:$K$57, MATCH(LARGE(Grupos!$T$54:$T$57, 1), Grupos!$T$54:$T$57, 0)) | C10: =INDEX(Grupos!$K$54:$K$57, MATCH(LARGE(Grupos!$T$54:$T$57, 2), Grupos!$T$54:$T$57, 0)) | D10: =INDEX(Grupos!$K$54:$K$57, MATCH(LARGE(Grupos!$T$54:$T$57, 3), Grupos!$T$54:$T$57, 0)) | E10: =LARGE(Grupos!$T$54:$T$57, 3)
A11: J | B11: =INDEX(Grupos!$K$60:$K$63, MATCH(LARGE(Grupos!$T$60:$T$63, 1), Grupos!$T$60:$T$63, 0)) | C11: =INDEX(Grupos!$K$60:$K$63, MATCH(LARGE(Grupos!$T$60:$T$63, 2), Grupos!$T$60:$T$63, 0)) | D11: =INDEX(Grupos!$K$60:$K$63, MATCH(LARGE(Grupos!$T$60:$T$63, 3), Grupos!$T$60:$T$63, 0)) | E11: =LARGE(Grupos!$T$60:$T$63, 3)
A12: K | B12: =INDEX(Grupos!$K$66:$K$69, MATCH(LARGE(Grupos!$T$66:$T$69, 1), Grupos!$T$66:$T$69, 0)) | C12: =INDEX(Grupos!$K$66:$K$69, MATCH(LARGE(Grupos!$T$66:$T$69, 2), Grupos!$T$66:$T$69, 0)) | D12: =INDEX(Grupos!$K$66:$K$69, MATCH(LARGE(Grupos!$T$66:$T$69, 3), Grupos!$T$66:$T$69, 0)) | E12: =LARGE(Grupos!$T$66:$T$69, 3)
A13: L | B13: =INDEX(Grupos!$K$72:$K$75, MATCH(LARGE(Grupos!$T$72:$T$75, 1), Grupos!$T$72:$T$75, 0)) | C13: =INDEX(Grupos!$K$72:$K$75, MATCH(LARGE(Grupos!$T$72:$T$75, 2), Grupos!$T$72:$T$75, 0)) | D13: =INDEX(Grupos!$K$72:$K$75, MATCH(LARGE(Grupos!$T$72:$T$75, 3), Grupos!$T$72:$T$75, 0)) | E13: =LARGE(Grupos!$T$72:$T$75, 3)
B14: =B5 | C14: =INDEX($C$16:$C$23, MATCH(VLOOKUP($D$25, MatrizTerceros!$A$1:$I$495, 4, FALSE), $B$16:$B$23, 0))
A15: Rank | B15: Grupo 3ro | C15: Equipo 3ro
A16: =LARGE($E$2:$E$13, 1) | B16: =INDEX($A$2:$A$13, MATCH(A16, $E$2:$E$13, 0)) | C16: =INDEX($D$2:$D$13, MATCH(A16, $E$2:$E$13, 0))
A17: =LARGE($E$2:$E$13, 2) | B17: =INDEX($A$2:$A$13, MATCH(A17, $E$2:$E$13, 0)) | C17: =INDEX($D$2:$D$13, MATCH(A17, $E$2:$E$13, 0))
A18: =LARGE($E$2:$E$13, 3) | B18: =INDEX($A$2:$A$13, MATCH(A18, $E$2:$E$13, 0)) | C18: =INDEX($D$2:$D$13, MATCH(A18, $E$2:$E$13, 0))
A19: =LARGE($E$2:$E$13, 4) | B19: =INDEX($A$2:$A$13, MATCH(A19, $E$2:$E$13, 0)) | C19: =INDEX($D$2:$D$13, MATCH(A19, $E$2:$E$13, 0))
A20: =LARGE($E$2:$E$13, 5) | B20: =INDEX($A$2:$A$13, MATCH(A20, $E$2:$E$13, 0)) | C20: =INDEX($D$2:$D$13, MATCH(A20, $E$2:$E$13, 0))
A21: =LARGE($E$2:$E$13, 6) | B21: =INDEX($A$2:$A$13, MATCH(A21, $E$2:$E$13, 0)) | C21: =INDEX($D$2:$D$13, MATCH(A21, $E$2:$E$13, 0))
A22: =LARGE($E$2:$E$13, 7) | B22: =INDEX($A$2:$A$13, MATCH(A22, $E$2:$E$13, 0)) | C22: =INDEX($D$2:$D$13, MATCH(A22, $E$2:$E$13, 0))
A23: =LARGE($E$2:$E$13, 8) | B23: =INDEX($A$2:$A$13, MATCH(A23, $E$2:$E$13, 0)) | C23: =INDEX($D$2:$D$13, MATCH(A23, $E$2:$E$13, 0))
A24: =LARGE($E$2:$E$13, 9) | B24: =INDEX($A$2:$A$13, MATCH(A24, $E$2:$E$13, 0)) | C24: =INDEX($D$2:$D$13, MATCH(A24, $E$2:$E$13, 0))
A25: =LARGE($E$2:$E$13, 10) | B25: =INDEX($A$2:$A$13, MATCH(A25, $E$2:$E$13, 0)) | C25: =INDEX($D$2:$D$13, MATCH(A25, $E$2:$E$13, 0)) | D25: =""&IF(COUNTIF($B$16:$B$23,"A"),"A","")&IF(COUNTIF($B$16:$B$23,"B"),"B","")&IF(COUNTIF($B$16:$B$23,"C"),"C","")&IF(COUNTIF($B$16:$B$23,"D"),"D","")&IF(COUNTIF($B$16:$B$23,"E"),"E","")&IF(COUNTIF($B$16:$B$23,"F"),"F","")&IF(COUNTIF($B$16:$B$23,"G"),"G","")&IF(COUNTIF($B$16:$B$23,"H"),"H","")&IF(COUNTIF($B$16:$B$23,"I"),"I","")&IF(COUNTIF($B$16:$B$23,"J"),"J","")&IF(COUNTIF($B$16:$B$23,"K"),"K","")&IF(COUNTIF($B$16:$B$23,"L"),"L","")
A26: =LARGE($E$2:$E$13, 11) | B26: =INDEX($A$2:$A$13, MATCH(A26, $E$2:$E$13, 0)) | C26: =INDEX($D$2:$D$13, MATCH(A26, $E$2:$E$13, 0))
A27: =LARGE($E$2:$E$13, 12) | B27: =INDEX($A$2:$A$13, MATCH(A27, $E$2:$E$13, 0)) | C27: =INDEX($D$2:$D$13, MATCH(A27, $E$2:$E$13, 0))
A29: M# | B29: Team 1 | C29: Combo 3ros: | D29: =""&IF(COUNTIF($B$16:$B$23,"A"),"A","")&IF(COUNTIF($B$16:$B$23,"B"),"B","")&IF(COUNTIF($B$16:$B$23,"C"),"C","")&IF(COUNTIF($B$16:$B$23,"D"),"D","")&IF(COUNTIF($B$16:$B$23,"E"),"E","")&IF(COUNTIF($B$16:$B$23,"F"),"F","")&IF(COUNTIF($B$16:$B$23,"G"),"G","")&IF(COUNTIF($B$16:$B$23,"H"),"H","")&IF(COUNTIF($B$16:$B$23,"I"),"I","")&IF(COUNTIF($B$16:$B$23,"J"),"J","")&IF(COUNTIF($B$16:$B$23,"K"),"K","")&IF(COUNTIF($B$16:$B$23,"L"),"L","")

Sheet Eliminatorias
A1: FASE FINAL (ELIMINACIÓN DIRECTA)
A4: DIECISEISAVOS DE FINAL (Ronda de 32)
A5: Partido | B5: Equipo A | C5: Goles | D5: vs | E5: Goles | F5: Equipo B | G5: Clasifica | H5: Estado
A6: 1/16 - P1 | B6: =Backend!C2 | C6: 1 | D6: - | E6: 2 | F6: =Backend!C3 | G6: =IF(AND(ISNUMBER(C6),ISNUMBER(E6)),IF(C6>E6,B6,F6),"")
A7: 1/16 - P2 | B7: =Backend!B7 | C7: 1 | D7: - | E7: 3 | F7: =Backend!C4 | G7: =IF(AND(ISNUMBER(C7),ISNUMBER(E7)),IF(C7>E7,B7,F7),"")
A8: 1/16 - P3 | B8: =Backend!B6 | C8: 2 | D8: - | E8: 3 | F8: =INDEX(Backend!$C$16:$C$23, MATCH(VLOOKUP(Backend!$D$29, MatrizTerceros!$A$1:$I$495, 5, FALSE), Backend!$B$16:$B$23, 0)) | G8: =IF(AND(ISNUMBER(C8),ISNUMBER(E8)),IF(C8>E8,B8,F8),"")
A9: 1/16 - P4 | B9: =Backend!B10 | C9: 3 | D9: - | E9: 3 | F9: =INDEX(Backend!$C$16:$C$23, MATCH(VLOOKUP(Backend!$D$29, MatrizTerceros!$A$1:$I$495, 7, FALSE), Backend!$B$16:$B$23, 0)) | G9: =IF(AND(ISNUMBER(C9),ISNUMBER(E9)),IF(C9>E9,B9,F9),"")
A10: 1/16 - P5 | B10: =Backend!B4 | C10: 1 | D10: - | E10: 3 | F10: =Backend!C7 | G10: =IF(AND(ISNUMBER(C10),ISNUMBER(E10)),IF(C10>E10,B10,F10),"")
A11: 1/16 - P6 | B11: =Backend!C6 | C11: 2 | D11: - | E11: 3 | F11: =Backend!C10 | G11: =IF(AND(ISNUMBER(C11),ISNUMBER(E11)),IF(C11>E11,B11,F11),"")
A12: 1/16 - P7 | B12: =Backend!B2 | C12: 3 | D12: - | E12: 0 | F12: =INDEX(Backend!$C$16:$C$23, MATCH(VLOOKUP(Backend!$D$29, MatrizTerceros!$A$1:$I$495, 2, FALSE), Backend!$B$16:$B$23, 0)) | G12: =IF(AND(ISNUMBER(C12),ISNUMBER(E12)),IF(C12>E12,B12,F12),"")
A13: 1/16 - P8 | B13: =Backend!B13 | C13: 1 | D13: - | E13: 3 | F13: =INDEX(Backend!$C$16:$C$23, MATCH(VLOOKUP(Backend!$D$29, MatrizTerceros!$A$1:$I$495, 9, FALSE), Backend!$B$16:$B$23, 0)) | G13: =IF(AND(ISNUMBER(C13),ISNUMBER(E13)),IF(C13>E13,B13,F13),"")
A14: 1/16 - P9 | B14: =Backend!B5 | C14: 0 | D14: - | E14: 2 | F14: =INDEX(Backend!$C$16:$C$23, MATCH(VLOOKUP(Backend!$D$29, MatrizTerceros!$A$1:$I$495, 4, FALSE), Backend!$B$16:$B$23, 0)) | G14: =IF(AND(ISNUMBER(C14),ISNUMBER(E14)),IF(C14>E14,B14,F14),"")
A15: 1/16 - P10 | B15: =Backend!B8 | C15: 2 | D15: - | E15: 2 | F15: =INDEX(Backend!$C$16:$C$23, MATCH(VLOOKUP(Backend!$D$29, MatrizTerceros!$A$1:$I$495, 6, FALSE), Backend!$B$16:$B$23, 0)) | G15: =IF(AND(ISNUMBER(C15),ISNUMBER(E15)),IF(C15>E15,B15,F15),"")
A16: 1/16 - P11 | B16: =Backend!C12 | C16: 1 | D16: - | E16: 1 | F16: =Backend!C13 | G16: =IF(AND(ISNUMBER(C16),ISNUMBER(E16)),IF(C16>E16,B16,F16),"")
A17: 1/16 - P12 | B17: =Backend!B9 | C17: 3 | D17: - | E17: 0 | F17: =Backend!C11 | G17: =IF(AND(ISNUMBER(C17),ISNUMBER(E17)),IF(C17>E17,B17,F17),"")
A18: 1/16 - P13 | B18: =Backend!B3 | C18: 2 | D18: - | E18: 0 | F18: =INDEX(Backend!$C$16:$C$23, MATCH(VLOOKUP(Backend!$D$29, MatrizTerceros!$A$1:$I$495, 3, FALSE), Backend!$B$16:$B$23, 0)) | G18: =IF(AND(ISNUMBER(C18),ISNUMBER(E18)),IF(C18>E18,B18,F18),"")
A19: 1/16 - P14 | B19: =Backend!B12 | C19: 1 | D19: - | E19: 0 | F19: =INDEX(Backend!$C$16:$C$23, MATCH(VLOOKUP(Backend!$D$29, MatrizTerceros!$A$1:$I$495, 8, FALSE), Backend!$B$16:$B$23, 0)) | G19: =IF(AND(ISNUMBER(C19),ISNUMBER(E19)),IF(C19>E19,B19,F19),"")
A20: 1/16 - P15 | B20: =Backend!B11 | C20: 1 | D20: - | E20: 0 | F20: =Backend!C9 | G20: =IF(AND(ISNUMBER(C20),ISNUMBER(E20)),IF(C20>E20,B20,F20),"")
A21: 1/16 - P16 | B21: =Backend!C5 | C21: 0 | D21: - | E21: 1 | F21: =Backend!C8 | G21: =IF(AND(ISNUMBER(C21),ISNUMBER(E21)),IF(C21>E21,B21,F21),"")
A23: OCTAVOS DE FINAL
A25: 1/8 - P1 | B25: =G6 | C25: 3 | D25: - | E25: 2 | F25: =G7 | G25: =IF(AND(ISNUMBER(C25),ISNUMBER(E25)),IF(C25>E25,B25,F25),"")
A26: 1/8 - P2 | B26: =G8 | C26: 2 | D26: - | E26: 1 | F26: =G9 | G26: =IF(AND(ISNUMBER(C26),ISNUMBER(E26)),IF(C26>E26,B26,F26),"")
A27: 1/8 - P3 | B27: =G10 | C27: 3 | D27: - | E27: 0 | F27: =G11 | G27: =IF(AND(ISNUMBER(C27),ISNUMBER(E27)),IF(C27>E27,B27,F27),"")
A28: 1/8 - P4 | B28: =G12 | C28: 1 | D28: - | E28: 2 | F28: =G13 | G28: =IF(AND(ISNUMBER(C28),ISNUMBER(E28)),IF(C28>E28,B28,F28),"")
A29: 1/8 - P5 | B29: =G14 | C29: 1 | D29: - | E29: 0 | F29: =G15 | G29: =IF(AND(ISNUMBER(C29),ISNUMBER(E29)),IF(C29>E29,B29,F29),"")
A30: 1/8 - P6 | B30: =G16 | C30: 1 | D30: - | E30: 0 | F30: =G17 | G30: =IF(AND(ISNUMBER(C30),ISNUMBER(E30)),IF(C30>E30,B30,F30),"")
A31: 1/8 - P7 | B31: =G18 | C31: 2 | D31: - | E31: 3 | F31: =G19 | G31: =IF(AND(ISNUMBER(C31),ISNUMBER(E31)),IF(C31>E31,B31,F31),"")
A32: 1/8 - P8 | B32: =G20 | C32: 1 | D32: - | E32: 0 | F32: =G21 | G32: =IF(AND(ISNUMBER(C32),ISNUMBER(E32)),IF(C32>E32,B32,F32),"")
A35: CUARTOS DE FINAL
A36: Partido | B36: Equipo A | C36: Goles | D36: vs | E36: Goles | F36: Equipo B | G36: Clasifica | H36: Estado
A37: 1/4 - P1 | B37: =G25 | C37: 2 | D37: - | E37: 3 | F37: =G26 | G37: =IF(AND(ISNUMBER(C37),ISNUMBER(E37)),IF(C37>E37,B37,F37),"")
A38: 1/4 - P2 | B38: =G27 | C38: 3 | D38: - | E38: 2 | F38: =G28 | G38: =IF(AND(ISNUMBER(C38),ISNUMBER(E38)),IF(C38>E38,B38,F38),"")
A39: 1/4 - P3 | B39: =G29 | C39: 1 | D39: - | E39: 0 | F39: =G30 | G39: =IF(AND(ISNUMBER(C39),ISNUMBER(E39)),IF(C39>E39,B39,F39),"")
A40: 1/4 - P4 | B40: =G31 | C40: 2 | D40: - | E40: 0 | F40: =G32 | G40: =IF(AND(ISNUMBER(C40),ISNUMBER(E40)),IF(C40>E40,B40,F40),"")
A43: SEMIFINALES
A44: Partido | B44: Equipo A | C44: Goles | D44: vs | E44: Goles | F44: Equipo B | G44: Clasifica | H44: Estado
A45: Semi - P1 | B45: =G37 | C45: 1 | D45: - | E45: 2 | F45: =G38 | G45: =IF(AND(ISNUMBER(C45),ISNUMBER(E45)),IF(C45>E45,B45,F45),"")
A46: Semi - P2 | B46: =G39 | C46: 2 | D46: - | E46: 1 | F46: =G40 | G46: =IF(AND(ISNUMBER(C46),ISNUMBER(E46)),IF(C46>E46,B46,F46),"")
A49: PARTIDO POR EL TERCER LUGAR
A50: Partido | B50: Equipo A | C50: Goles | D50: vs | E50: Goles | F50: Equipo B | G50: Clasifica | H50: Estado
...

Sheet RankingFIFA
A1: México | B1: 1000
A2: Sudáfrica | B2: 1000
A3: Corea del Sur | B3: 1000
A4: Chequia | B4: 1000
A5: Canadá | B5: 1000
A6: Bosnia y Herze. | B6: 1000
A7: Qatar | B7: 1000
A8: Suiza | B8: 1000
A9: Brasil | B9: 1000
A10: Marruecos | B10: 1000
A11: Haití | B11: 1000
A12: Escocia | B12: 1000
... A48: Panamá | B48: 1000

Sheet MatrizTerceros
A1: ABCDEFGH | B1: C | C1: E | D1: B | E1: F | F1: A | G1: G | H1: D | I1: H
A2: ABCDEFGI | B2: C | C2: E | D2: B | E2: F | F2: A | G2: G | H2: D | I2: I
A3: ABCDEFGJ | B3: C | C3: E | D3: B | E3: F | F3: A | G3: G | H3: D | I3: J
A4: ABCDEFGK | B4: C | C4: E | D4: B | E4: F | F4: A | G4: G | H4: D | I4: K
A5: ABCDEFGL | B5: C | C5: F | D5: B | E5: D | F5: A | G5: G | H5: L | I5: E
A6: ABCDEFHI | B6: C | C6: E | D6: B | E6: A | F6: H | G6: F | H6: D | I6: I
A7: ABCDEFHJ | B7: C | C7: E | D7: B | E7: A | F7: H | G7: F | H7: D | I7: J
A8: ABCDEFHK | B8: C | C8: E | D8: B | E8: A | F8: H | G8: F | H8: D | I8: K
A9: ABCDEFHL | B9: C | C9: E | D9: B | E9: D | F9: A | G9: F | H9: L | I9: H
A10: ABCDEFIJ | B10: C | C10: E | D10: B | E10: A | F10: I | G10: F | H10: D | I10: J
A11: ABCDEFIK | B11: C | C11: E | D11: B | E11: A | F11: I | G11: F | H11: D | I11: K
A12: ABCDEFIL | B12: C | C12: E | D12: B | E12: D | F12: A | G12: F | H12: L | I12: I
... A495: EFGHIJKL | B495: E | C495: G | D495: I | E495: F | F495: J | G495: H | H495: L | I495: K
